Workbook

Sheet Read Me
A1: Urban Integrated Municipal ERP: GWMC project plan
A2: Hake Technologies | Version 0.1 draft | 23 October 2026 | Based on product SRS v0.35 and Technical Architecture v0.1
A4: What is in this workbook
A5: Assumptions: project start date, contingency, holidays and optional day rates. Yellow cells are yours to change; everything else recalculates.
A6: Project Plan: phases, tasks and subtasks with start offset, duration, dates, predecessors, effort in person-days by team role, and a monthly Gantt.
A7: Team Summary: effort by phase and by module for each team role, with contingency and optional cost.
A8: Resource Loading: full-time staff needed per role per month, from the Gantt allocation.
A9: Milestones: phase go-lives and sign-offs with dates.
A10: Planner Import: one row per subtask (title, bucket, start, due, label, effort, notes) for Microsoft Planner in Teams.
A11: MS Project Import: ID, name, outline level, duration, start, finish, predecessors and work, for the Microsoft Project import wizard.
A12: Risks: top delivery risks with owners and mitigations.
A14: How to edit
... A27: These are planning estimates for a first plan. Refine them with the module teams after the Phase 1 design workshops.

Sheet Assumptions
A1: Assumptions and inputs
A3: Item | C3: Value | D3: Note | F3: Holidays (enter GWMC / Telangana holidays)
A4: Project start date (Monday) | C4: 46328 | D4: Assumed; set to the agreed start
A5: Contingency on effort | C5: 0.15 | D5: Assumed 15% for estimation uncertainty
A6: Working hours per person-day | C6: 8 | D6: Standard day
A7: Currency for optional costing | C7: INR | D7: Day rates below are optional
A10: Team roles and optional day rates
A11: Code | B11: Role | C11: Day rate (optional)
A12: PM | B12: Project manager | C12: 0
A13: BA | B13: Business analyst | C13: 0
A14: ARC | B14: Solution / technical architect | C14: 0
A15: BE | B15: Backend developer | C15: 0
A16: FE | B16: Frontend developer | C16: 0
A17: MOB | B17: Mobile developer | C17: 0
A18: GIS | B18: GIS engineer | C18: 0
A19: DEV | B19: DevOps / infrastructure | C19: 0
A20: QA | B20: QA / test engineer | C20: 0
A21: DATA | B21: Data migration engineer | C21: 0
A22: TRN | B22: Trainer / change manager | C22: 0

Sheet Project Plan
A1: Project plan: Urban ERP for GWMC (all phases)
A2: Blue = editable estimates. Dates use working days from the start date and holidays on the Assumptions sheet. Gantt cells show the share of each subtask falling in that month.
AF3: Gantt (share of subtask effort per month)
A4: ID | B4: WBS | C4: Level | D4: Type | E4: Task / subtask | F4: Phase | G4: Module | H4: Lead team | I4: Start offset (wd) | J4: Duration (wd) | K4: Start | L4: Finish | M4: Predecessors (ID) | N4: PM | O4: BA | P4: ARC | Q4: BE | R4: FE | S4: MOB | T4: GIS | U4: DEV | V4: QA | W4: DATA | X4: TRN | Y4: Total effort (pd) | Z4: Effort + contingency (pd) | AA4: Deliverable / reference | AB4: Status | AC4: Owner | AD4: % complete | AF4: =EDATE(DATE(YEAR(Assumptions!$C$4),MONTH(Assumptions!$C$4),1),0) -> 46327 | AG4: =EDATE(DATE(YEAR(Assumptions!$C$4),MONTH(Assumptions!$C$4),1),1) -> 46357 | AH4: =EDATE(DATE(YEAR(Assumptions!$C$4),MONTH(Assumptions!$C$4),1),2) -> 46388 | AI4: =EDATE(DATE(YEAR(Assumptions!$C$4),MONTH(Assumptions!$C$4),1),3) -> 46419 | AJ4: =EDATE(DATE(YEAR(Assumptions!$C$4),MONTH(Assumptions!$C$4),1),4) -> 46447 | AK4: =EDATE(DATE(YEAR(Assumptions!$C$4),MONTH(Assumptions!$C$4),1),5) -> 46478 | AL4: =EDATE(DATE(YEAR(Assumptions!$C$4),MONTH(Assumptions!$C$4),1),6) -> 46508 | AM4: =EDATE(DATE(YEAR(Assumptions!$C$4),MONTH(Assumptions!$C$4),1),7) -> 46539 | AN4: =EDATE(DATE(YEAR(Assumptions!$C$4),MONTH(Assumptions!$C$4),1),8) -> 46569 | AO4: =EDATE(DATE(YEAR(Assumptions!$C$4),MONTH(Assumptions!$C$4),1),9) -> 46600 | AP4: =EDATE(DATE(YEAR(Assumptions!$C$4),MONTH(Assumptions!$C$4),1),10) -> 46631 | AQ4: =EDATE(DATE(YEAR(Assumptions!$C$4),MONTH(Assumptions!$C$4),1),11) -> 46661 | AR4: =EDATE(DATE(YEAR(Assumptions!$C$4),MONTH(Assumptions!$C$4),1),12) -> 46692 | AS4: =EDATE(DATE(YEAR(Assumptions!$C$4),MONTH(Assumptions!$C$4),1),13) -> 46722 | AT4: =EDATE(DATE(YEAR(Assumptions!$C$4),MONTH(Assumptions!$C$4),1),14) -> 46753 | AU4: =EDATE(DATE(YEAR(Assumptions!$C$4),MONTH(Assumptions!$C$4),1),15) -> 46784 | AV4: =EDATE(DATE(YEAR(Assumptions!$C$4),MONTH(Assumptions!$C$4),1),16) -> 46813 | AW4: =EDATE(DATE(YEAR(Assumptions!$C$4),MONTH(Assumptions!$C$4),1),17) -> 46844 | AX4: =EDATE(DATE(YEAR(Assumptions!$C$4),MONTH(Assumptions!$C$4),1),18) -> 46874 | AY4: =EDATE(DATE(YEAR(Assumptions!$C$4),MONTH(Assumptions!$C$4),1),19) -> 46905 | AZ4: =EDATE(DATE(YEAR(Assumptions!$C$4),MONTH(Assumptions!$C$4),1),20) -> 46935 | BA4: =EDATE(DATE(YEAR(Assumptions!$C$4),MONTH(Assumptions!$C$4),1),21) -> 46966 | BB4: =EDATE(DATE(YEAR(Assumptions!$C$4),MONTH(Assumptions!$C$4),1),22) -> 46997 | BC4: =EDATE(DATE(YEAR(Assumptions!$C$4),MONTH(Assumptions!$C$4),1),23) -> 47027
A5: 1 | B5: 1 | C5: 1 | D5: Phase | E5: Programme management and governance | F5: All | J5: =NETWORKDAYS(K5,L5,Assumptions!$F$4:$F$44) -> 440 | K5: =MIN(K6:K14) -> 46328 | L5: =MAX(L6:L14) -> 46941 | N5: =SUMPRODUCT(($C$6:$C$14=3)*(N6:N14)) -> 345 | O5: =SUMPRODUCT(($C$6:$C$14=3)*(O6:O14)) -> 30 | P5: =SUMPRODUCT(($C$6:$C$14=3)*(P6:P14)) -> 89 | Q5: =SUMPRODUCT(($C$6:$C$14=3)*(Q6:Q14)) -> 30 | R5: =SUMPRODUCT(($C$6:$C$14=3)*(R6:R14)) -> 0 | S5: =SUMPRODUCT(($C$6:$C$14=3)*(S6:S14)) -> 0 | T5: =SUMPRODUCT(($C$6:$C$14=3)*(T6:T14)) -> 0 | U5: =SUMPRODUCT(($C$6:$C$14=3)*(U6:U14)) -> 15 | ... X5: =SUMPRODUCT(($C$6:$C$14=3)*(X6:X14)) -> 10 | Y5: =SUM(N5:X5) -> 527 | Z5: =Y5*(1+Assumptions!$C$5) -> 606.05 | AF5: 0 | AG5: 0 | AH5: 0 | AI5: 0 | AJ5: 0 | AK5: 0 | AL5: 0 | AM5: 0 | AN5: 0 | AO5: 0 | AP5: 0 | AQ5: 0 | AR5: 0 | AS5: 0 | AT5: 0 | AU5: 0 | AV5: 0 | AW5: 0 | AX5: 0 | AY5: 0 | AZ5: 0 | BA5: 0 | BB5: 0 | BC5: 0
A6: 2 | B6: 1.1 | C6: 2 | D6: Task | E6: Project governance and PMO | F6: All | J6: =NETWORKDAYS(K6,L6,Assumptions!$F$4:$F$44) -> 440 | K6: =MIN(K7:K11) -> 46328 | L6: =MAX(L7:L11) -> 46941 | N6: =SUMPRODUCT(($C$7:$C$11=3)*(N7:N11)) -> 313 | O6: =SUMPRODUCT(($C$7:$C$11=3)*(O7:O11)) -> 10 | P6: =SUMPRODUCT(($C$7:$C$11=3)*(P7:P11)) -> 71 | Q6: =SUMPRODUCT(($C$7:$C$11=3)*(Q7:Q11)) -> 30 | R6: =SUMPRODUCT(($C$7:$C$11=3)*(R7:R11)) -> 0 | S6: =SUMPRODUCT(($C$7:$C$11=3)*(S7:S11)) -> 0 | T6: =SUMPRODUCT(($C$7:$C$11=3)*(T7:T11)) -> 0 | U6: =SUMPRODUCT(($C$7:$C$11=3)*(U7:U11)) -> 15 | ... X6: =SUMPRODUCT(($C$7:$C$11=3)*(X7:X11)) -> 10 | Y6: =SUM(N6:X6) -> 449 | Z6: =Y6*(1+Assumptions!$C$5) -> 516.35 | AF6: 0 | AG6: 0 | AH6: 0 | AI6: 0 | AJ6: 0 | AK6: 0 | AL6: 0 | AM6: 0 | AN6: 0 | AO6: 0 | AP6: 0 | AQ6: 0 | AR6: 0 | AS6: 0 | AT6: 0 | AU6: 0 | AV6: 0 | AW6: 0 | AX6: 0 | AY6: 0 | AZ6: 0 | BA6: 0 | BB6: 0 | BC6: 0
A7: 3 | B7: 1.1.1 | C7: 3 | D7: Subtask | E7: PMO, planning, status reporting and steering committee: Phase 1 | F7: All | H7: PM | I7: 0 | J7: 140 | K7: =WORKDAY(Assumptions!$C$4,I7,Assumptions!$F$4:$F$44) -> 46328 | L7: =IF(J7=0,K7,WORKDAY(K7,J7-1,Assumptions!$F$4:$F$44)) -> 46521 | N7: 70 | O7: 0 | P7: 14 | Q7: 0 | R7: 0 | S7: 0 | T7: 0 | U7: 0 | V7: 0 | W7: 0 | X7: 0 | Y7: =SUM(N7:X7) -> 84 | Z7: =Y7*(1+Assumptions!$C$5) -> 96.6 | AA7: Weekly status, monthly steering minutes, RAID log | AB7: Not started | AD7: 0 | AF7: =IF($J7=0,0,MAX(0,NETWORKDAYS(MAX($K7,AF$4),MIN($L7,EOMONTH(AF$4,0)),Assumptions!$F$4:$F$44))/NETWORKDAYS($K7,$L7,Assumptions!$F$4:$F$44)) -> 0.15 | AG7: =IF($J7=0,0,MAX(0,NETWORKDAYS(MAX($K7,AG$4),MIN($L7,EOMONTH(AG$4,0)),Assumptions!$F$4:$F$44))/NETWORKDAYS($K7,$L7,Assumptions!$F$4:$F$44)) -> 0.16428571 | AH7: =IF($J7=0,0,MAX(0,NETWORKDAYS(MAX($K7,AH$4),MIN($L7,EOMONTH(AH$4,0)),Assumptions!$F$4:$F$44))/NETWORKDAYS($K7,$L7,Assumptions!$F$4:$F$44)) -> 0.15 | AI7: =IF($J7=0,0,MAX(0,NETWORKDAYS(MAX($K7,AI$4),MIN($L7,EOMONTH(AI$4,0)),Assumptions!$F$4:$F$44))/NETWORKDAYS($K7,$L7,Assumptions!$F$4:$F$44)) -> 0.14285714 | AJ7: =IF($J7=0,0,MAX(0,NETWORKDAYS(MAX($K7,AJ$4),MIN($L7,EOMONTH(AJ$4,0)),Assumptions!$F$4:$F$44))/NETWORKDAYS($K7,$L7,Assumptions!$F$4:$F$44)) -> 0.16428571 | AK7: =IF($J7=0,0,MAX(0,NETWORKDAYS(MAX($K7,AK$4),MIN($L7,EOMONTH(AK$4,0)),Assumptions!$F$4:$F$44))/NETWORKDAYS($K7,$L7,Assumptions!$F$4:$F$44)) -> 0.15714286 | AL7: =IF($J7=0,0,MAX(0,NETWORKDAYS(MAX($K7,AL$4),MIN($L7,EOMONTH(AL$4,0)),Assumptions!$F$4:$F$44))/NETWORKDAYS($K7,$L7,Assumptions!$F$4:$F$44)) -> 0.071428571 | AM7: =IF($J7=0,0,MAX(0,NETWORKDAYS(MAX($K7,AM$4),MIN($L7,EOMONTH(AM$4,0)),Assumptions!$F$4:$F$44))/NETWORKDAYS($K7,$L7,Assumptions!$F$4:$F$44)) -> 0 | ... BC7: =IF($J7=0,0,MAX(0,NETWORKDAYS(MAX($K7,BC$4),MIN($L7,EOMONTH(BC$4,0)),Assumptions!$F$4:$F$44))/NETWORKDAYS($K7,$L7,Assumptions!$F$4:$F$44)) -> 0
A8: 4 | B8: 1.1.2 | C8: 3 | D8: Subtask | E8: PMO, planning, status reporting and steering committee: Phase 2 | F8: All | H8: PM | I8: 88 | J8: 141 | K8: =WORKDAY(Assumptions!$C$4,I8,Assumptions!$F$4:$F$44) -> 46450 | L8: =IF(J8=0,K8,WORKDAY(K8,J8-1,Assumptions!$F$4:$F$44)) -> 46646 | N8: 71 | O8: 0 | P8: 14 | Q8: 0 | R8: 0 | S8: 0 | T8: 0 | U8: 0 | V8: 0 | W8: 0 | X8: 0 | Y8: =SUM(N8:X8) -> 85 | Z8: =Y8*(1+Assumptions!$C$5) -> 97.75 | AA8: Weekly status, monthly steering minutes, RAID log | AB8: Not started | AD8: 0 | AF8: =IF($J8=0,0,MAX(0,NETWORKDAYS(MAX($K8,AF$4),MIN($L8,EOMONTH(AF$4,0)),Assumptions!$F$4:$F$44))/NETWORKDAYS($K8,$L8,Assumptions!$F$4:$F$44)) -> 0 | AG8: =IF($J8=0,0,MAX(0,NETWORKDAYS(MAX($K8,AG$4),MIN($L8,EOMONTH(AG$4,0)),Assumptions!$F$4:$F$44))/NETWORKDAYS($K8,$L8,Assumptions!$F$4:$F$44)) -> 0 | AH8: =IF($J8=0,0,MAX(0,NETWORKDAYS(MAX($K8,AH$4),MIN($L8,EOMONTH(AH$4,0)),Assumptions!$F$4:$F$44))/NETWORKDAYS($K8,$L8,Assumptions!$F$4:$F$44)) -> 0 | AI8: =IF($J8=0,0,MAX(0,NETWORKDAYS(MAX($K8,AI$4),MIN($L8,EOMONTH(AI$4,0)),Assumptions!$F$4:$F$44))/NETWORKDAYS($K8,$L8,Assumptions!$F$4:$F$44)) -> 0 | AJ8: =IF($J8=0,0,MAX(0,NETWORKDAYS(MAX($K8,AJ$4),MIN($L8,EOMONTH(AJ$4,0)),Assumptions!$F$4:$F$44))/NETWORKDAYS($K8,$L8,Assumptions!$F$4:$F$44)) -> 0.14184397 | AK8: =IF($J8=0,0,MAX(0,NETWORKDAYS(MAX($K8,AK$4),MIN($L8,EOMONTH(AK$4,0)),Assumptions!$F$4:$F$44))/NETWORKDAYS($K8,$L8,Assumptions!$F$4:$F$44)) -> 0.15602837 | AL8: =IF($J8=0,0,MAX(0,NETWORKDAYS(MAX($K8,AL$4),MIN($L8,EOMONTH(AL$4,0)),Assumptions!$F$4:$F$44))/NETWORKDAYS($K8,$L8,Assumptions!$F$4:$F$44)) -> 0.14893617 | AM8: =IF($J8=0,0,MAX(0,NETWORKDAYS(MAX($K8,AM$4),MIN($L8,EOMONTH(AM$4,0)),Assumptions!$F$4:$F$44))/NETWORKDAYS($K8,$L8,Assumptions!$F$4:$F$44)) -> 0.15602837 | ... BC8: =IF($J8=0,0,MAX(0,NETWORKDAYS(MAX($K8,BC$4),MIN($L8,EOMONTH(BC$4,0)),Assumptions!$F$4:$F$44))/NETWORKDAYS($K8,$L8,Assumptions!$F$4:$F$44)) -> 0
A9: 5 | B9: 1.1.3 | C9: 3 | D9: Subtask | E9: PMO, planning, status reporting and steering committee: Phase 3 | F9: All | H9: PM | I9: 176 | J9: 141 | K9: =WORKDAY(Assumptions!$C$4,I9,Assumptions!$F$4:$F$44) -> 46574 | L9: =IF(J9=0,K9,WORKDAY(K9,J9-1,Assumptions!$F$4:$F$44)) -> 46770 | N9: 71 | O9: 0 | P9: 14 | Q9: 0 | R9: 0 | S9: 0 | T9: 0 | U9: 0 | V9: 0 | W9: 0 | X9: 0 | Y9: =SUM(N9:X9) -> 85 | Z9: =Y9*(1+Assumptions!$C$5) -> 97.75 | AA9: Weekly status, monthly steering minutes, RAID log | AB9: Not started | AD9: 0 | AF9: =IF($J9=0,0,MAX(0,NETWORKDAYS(MAX($K9,AF$4),MIN($L9,EOMONTH(AF$4,0)),Assumptions!$F$4:$F$44))/NETWORKDAYS($K9,$L9,Assumptions!$F$4:$F$44)) -> 0 | AG9: =IF($J9=0,0,MAX(0,NETWORKDAYS(MAX($K9,AG$4),MIN($L9,EOMONTH(AG$4,0)),Assumptions!$F$4:$F$44))/NETWORKDAYS($K9,$L9,Assumptions!$F$4:$F$44)) -> 0 | AH9: =IF($J9=0,0,MAX(0,NETWORKDAYS(MAX($K9,AH$4),MIN($L9,EOMONTH(AH$4,0)),Assumptions!$F$4:$F$44))/NETWORKDAYS($K9,$L9,Assumptions!$F$4:$F$44)) -> 0 | AI9: =IF($J9=0,0,MAX(0,NETWORKDAYS(MAX($K9,AI$4),MIN($L9,EOMONTH(AI$4,0)),Assumptions!$F$4:$F$44))/NETWORKDAYS($K9,$L9,Assumptions!$F$4:$F$44)) -> 0 | AJ9: =IF($J9=0,0,MAX(0,NETWORKDAYS(MAX($K9,AJ$4),MIN($L9,EOMONTH(AJ$4,0)),Assumptions!$F$4:$F$44))/NETWORKDAYS($K9,$L9,Assumptions!$F$4:$F$44)) -> 0 | AK9: =IF($J9=0,0,MAX(0,NETWORKDAYS(MAX($K9,AK$4),MIN($L9,EOMONTH(AK$4,0)),Assumptions!$F$4:$F$44))/NETWORKDAYS($K9,$L9,Assumptions!$F$4:$F$44)) -> 0 | AL9: =IF($J9=0,0,MAX(0,NETWORKDAYS(MAX($K9,AL$4),MIN($L9,EOMONTH(AL$4,0)),Assumptions!$F$4:$F$44))/NETWORKDAYS($K9,$L9,Assumptions!$F$4:$F$44)) -> 0 | AM9: =IF($J9=0,0,MAX(0,NETWORKDAYS(MAX($K9,AM$4),MIN($L9,EOMONTH(AM$4,0)),Assumptions!$F$4:$F$44))/NETWORKDAYS($K9,$L9,Assumptions!$F$4:$F$44)) -> 0 | ... BC9: =IF($J9=0,0,MAX(0,NETWORKDAYS(MAX($K9,BC$4),MIN($L9,EOMONTH(BC$4,0)),Assumptions!$F$4:$F$44))/NETWORKDAYS($K9,$L9,Assumptions!$F$4:$F$44)) -> 0
A10: 6 | B10: 1.1.4 | C10: 3 | D10: Subtask | E10: PMO, planning, status reporting and steering committee: Phase 4 | F10: All | H10: PM | I10: 264 | J10: 141 | K10: =WORKDAY(Assumptions!$C$4,I10,Assumptions!$F$4:$F$44) -> 46696 | L10: =IF(J10=0,K10,WORKDAY(K10,J10-1,Assumptions!$F$4:$F$44)) -> 46892 | N10: 71 | O10: 0 | P10: 14 | Q10: 0 | R10: 0 | S10: 0 | T10: 0 | U10: 0 | V10: 0 | W10: 0 | X10: 0 | Y10: =SUM(N10:X10) -> 85 | Z10: =Y10*(1+Assumptions!$C$5) -> 97.75 | AA10: Weekly status, monthly steering minutes, RAID log | AB10: Not started | AD10: 0 | AF10: =IF($J10=0,0,MAX(0,NETWORKDAYS(MAX($K10,AF$4),MIN($L10,EOMONTH(AF$4,0)),Assumptions!$F$4:$F$44))/NETWORKDAYS($K10,$L10,Assumptions!$F$4:$F$44)) -> 0 | AG10: =IF($J10=0,0,MAX(0,NETWORKDAYS(MAX($K10,AG$4),MIN($L10,EOMONTH(AG$4,0)),Assumptions!$F$4:$F$44))/NETWORKDAYS($K10,$L10,Assumptions!$F$4:$F$44)) -> 0 | AH10: =IF($J10=0,0,MAX(0,NETWORKDAYS(MAX($K10,AH$4),MIN($L10,EOMONTH(AH$4,0)),Assumptions!$F$4:$F$44))/NETWORKDAYS($K10,$L10,Assumptions!$F$4:$F$44)) -> 0 | AI10: =IF($J10=0,0,MAX(0,NETWORKDAYS(MAX($K10,AI$4),MIN($L10,EOMONTH(AI$4,0)),Assumptions!$F$4:$F$44))/NETWORKDAYS($K10,$L10,Assumptions!$F$4:$F$44)) -> 0 | AJ10: =IF($J10=0,0,MAX(0,NETWORKDAYS(MAX($K10,AJ$4),MIN($L10,EOMONTH(AJ$4,0)),Assumptions!$F$4:$F$44))/NETWORKDAYS($K10,$L10,Assumptions!$F$4:$F$44)) -> 0 | AK10: =IF($J10=0,0,MAX(0,NETWORKDAYS(MAX($K10,AK$4),MIN($L10,EOMONTH(AK$4,0)),Assumptions!$F$4:$F$44))/NETWORKDAYS($K10,$L10,Assumptions!$F$4:$F$44)) -> 0 | AL10: =IF($J10=0,0,MAX(0,NETWORKDAYS(MAX($K10,AL$4),MIN($L10,EOMONTH(AL$4,0)),Assumptions!$F$4:$F$44))/NETWORKDAYS($K10,$L10,Assumptions!$F$4:$F$44)) -> 0 | AM10: =IF($J10=0,0,MAX(0,NETWORKDAYS(MAX($K10,AM$4),MIN($L10,EOMONTH(AM$4,0)),Assumptions!$F$4:$F$44))/NETWORKDAYS($K10,$L10,Assumptions!$F$4:$F$44)) -> 0 | ... BC10: =IF($J10=0,0,MAX(0,NETWORKDAYS(MAX($K10,BC$4),MIN($L10,EOMONTH(BC$4,0)),Assumptions!$F$4:$F$44))/NETWORKDAYS($K10,$L10,Assumptions!$F$4:$F$44)) -> 0
A11: 7 | B11: 1.1.5 | C11: 3 | D11: Subtask | E11: Final stabilisation, knowledge transfer and handover | F11: All | H11: PM | I11: 400 | J11: 40 | K11: =WORKDAY(Assumptions!$C$4,I11,Assumptions!$F$4:$F$44) -> 46888 | L11: =IF(J11=0,K11,WORKDAY(K11,J11-1,Assumptions!$F$4:$F$44)) -> 46941 | N11: 30 | O11: 10 | P11: 15 | Q11: 30 | R11: 0 | S11: 0 | T11: 0 | U11: 15 | V11: 0 | W11: 0 | X11: 10 | Y11: =SUM(N11:X11) -> 110 | Z11: =Y11*(1+Assumptions!$C$5) -> 126.5 | AA11: Handover pack, runbooks, KT sign-off | AB11: Not started | AD11: 0 | AF11: =IF($J11=0,0,MAX(0,NETWORKDAYS(MAX($K11,AF$4),MIN($L11,EOMONTH(AF$4,0)),Assumptions!$F$4:$F$44))/NETWORKDAYS($K11,$L11,Assumptions!$F$4:$F$44)) -> 0 | AG11: =IF($J11=0,0,MAX(0,NETWORKDAYS(MAX($K11,AG$4),MIN($L11,EOMONTH(AG$4,0)),Assumptions!$F$4:$F$44))/NETWORKDAYS($K11,$L11,Assumptions!$F$4:$F$44)) -> 0 | AH11: =IF($J11=0,0,MAX(0,NETWORKDAYS(MAX($K11,AH$4),MIN($L11,EOMONTH(AH$4,0)),Assumptions!$F$4:$F$44))/NETWORKDAYS($K11,$L11,Assumptions!$F$4:$F$44)) -> 0 | AI11: =IF($J11=0,0,MAX(0,NETWORKDAYS(MAX($K11,AI$4),MIN($L11,EOMONTH(AI$4,0)),Assumptions!$F$4:$F$44))/NETWORKDAYS($K11,$L11,Assumptions!$F$4:$F$44)) -> 0 | AJ11: =IF($J11=0,0,MAX(0,NETWORKDAYS(MAX($K11,AJ$4),MIN($L11,EOMONTH(AJ$4,0)),Assumptions!$F$4:$F$44))/NETWORKDAYS($K11,$L11,Assumptions!$F$4:$F$44)) -> 0 | AK11: =IF($J11=0,0,MAX(0,NETWORKDAYS(MAX($K11,AK$4),MIN($L11,EOMONTH(AK$4,0)),Assumptions!$F$4:$F$44))/NETWORKDAYS($K11,$L11,Assumptions!$F$4:$F$44)) -> 0 | AL11: =IF($J11=0,0,MAX(0,NETWORKDAYS(MAX($K11,AL$4),MIN($L11,EOMONTH(AL$4,0)),Assumptions!$F$4:$F$44))/NETWORKDAYS($K11,$L11,Assumptions!$F$4:$F$44)) -> 0 | AM11: =IF($J11=0,0,MAX(0,NETWORKDAYS(MAX($K11,AM$4),MIN($L11,EOMONTH(AM$4,0)),Assumptions!$F$4:$F$44))/NETWORKDAYS($K11,$L11,Assumptions!$F$4:$F$44)) -> 0 | ... BC11: =IF($J11=0,0,MAX(0,NETWORKDAYS(MAX($K11,BC$4),MIN($L11,EOMONTH(BC$4,0)),Assumptions!$F$4:$F$44))/NETWORKDAYS($K11,$L11,Assumptions!$F$4:$F$44)) -> 0
A12: 8 | B12: 1.2 | C12: 2 | D12: Task | E12: Change control and quality | F12: All | J12: =NETWORKDAYS(K12,L12,Assumptions!$F$4:$F$44) -> 400 | K12: =MIN(K13:K14) -> 46356 | L12: =MAX(L13:L14) -> 46913 | N12: =SUMPRODUCT(($C$13:$C$14=3)*(N13:N14)) -> 32 | O12: =SUMPRODUCT(($C$13:$C$14=3)*(O13:O14)) -> 20 | P12: =SUMPRODUCT(($C$13:$C$14=3)*(P13:P14)) -> 18 | Q12: =SUMPRODUCT(($C$13:$C$14=3)*(Q13:Q14)) -> 0 | R12: =SUMPRODUCT(($C$13:$C$14=3)*(R13:R14)) -> 0 | S12: =SUMPRODUCT(($C$13:$C$14=3)*(S13:S14)) -> 0 | T12: =SUMPRODUCT(($C$13:$C$14=3)*(T13:T14)) -> 0 | U12: =SUMPRODUCT(($C$13:$C$14=3)*(U13:U14)) -> 0 | ... X12: =SUMPRODUCT(($C$13:$C$14=3)*(X13:X14)) -> 0 | Y12: =SUM(N12:X12) -> 78 | Z12: =Y12*(1+Assumptions!$C$5) -> 89.7 | AF12: 0 | AG12: 0 | AH12: 0 | AI12: 0 | AJ12: 0 | AK12: 0 | AL12: 0 | AM12: 0 | AN12: 0 | AO12: 0 | AP12: 0 | AQ12: 0 | AR12: 0 | AS12: 0 | AT12: 0 | AU12: 0 | AV12: 0 | AW12: 0 | AX12: 0 | AY12: 0 | AZ12: 0 | BA12: 0 | BB12: 0 | BC12: 0
A13: 9 | B13: 1.2.1 | C13: 3 | D13: Subtask | E13: Change request process and impact assessments (whole programme) | F13: All | H13: PM | I13: 20 | J13: 400 | K13: =WORKDAY(Assumptions!$C$4,I13,Assumptions!$F$4:$F$44) -> 46356 | L13: =IF(J13=0,K13,WORKDAY(K13,J13-1,Assumptions!$F$4:$F$44)) -> 46913 | N13: 20 | O13: 20 | P13: 10 | Q13: 0 | R13: 0 | S13: 0 | T13: 0 | U13: 0 | V13: 0 | W13: 0 | X13: 0 | Y13: =SUM(N13:X13) -> 50 | Z13: =Y13*(1+Assumptions!$C$5) -> 57.5 | AA13: CR register | AB13: Not started | AD13: 0 | AF13: =IF($J13=0,0,MAX(0,NETWORKDAYS(MAX($K13,AF$4),MIN($L13,EOMONTH(AF$4,0)),Assumptions!$F$4:$F$44))/NETWORKDAYS($K13,$L13,Assumptions!$F$4:$F$44)) -> 0.0025 | AG13: =IF($J13=0,0,MAX(0,NETWORKDAYS(MAX($K13,AG$4),MIN($L13,EOMONTH(AG$4,0)),Assumptions!$F$4:$F$44))/NETWORKDAYS($K13,$L13,Assumptions!$F$4:$F$44)) -> 0.0575 | AH13: =IF($J13=0,0,MAX(0,NETWORKDAYS(MAX($K13,AH$4),MIN($L13,EOMONTH(AH$4,0)),Assumptions!$F$4:$F$44))/NETWORKDAYS($K13,$L13,Assumptions!$F$4:$F$44)) -> 0.0525 | AI13: =IF($J13=0,0,MAX(0,NETWORKDAYS(MAX($K13,AI$4),MIN($L13,EOMONTH(AI$4,0)),Assumptions!$F$4:$F$44))/NETWORKDAYS($K13,$L13,Assumptions!$F$4:$F$44)) -> 0.05 | AJ13: =IF($J13=0,0,MAX(0,NETWORKDAYS(MAX($K13,AJ$4),MIN($L13,EOMONTH(AJ$4,0)),Assumptions!$F$4:$F$44))/NETWORKDAYS($K13,$L13,Assumptions!$F$4:$F$44)) -> 0.0575 | AK13: =IF($J13=0,0,MAX(0,NETWORKDAYS(MAX($K13,AK$4),MIN($L13,EOMONTH(AK$4,0)),Assumptions!$F$4:$F$44))/NETWORKDAYS($K13,$L13,Assumptions!$F$4:$F$44)) -> 0.055 | AL13: =IF($J13=0,0,MAX(0,NETWORKDAYS(MAX($K13,AL$4),MIN($L13,EOMONTH(AL$4,0)),Assumptions!$F$4:$F$44))/NETWORKDAYS($K13,$L13,Assumptions!$F$4:$F$44)) -> 0.0525 | AM13: =IF($J13=0,0,MAX(0,NETWORKDAYS(MAX($K13,AM$4),MIN($L13,EOMONTH(AM$4,0)),Assumptions!$F$4:$F$44))/NETWORKDAYS($K13,$L13,Assumptions!$F$4:$F$44)) -> 0.055 | ... BC13: =IF($J13=0,0,MAX(0,NETWORKDAYS(MAX($K13,BC$4),MIN($L13,EOMONTH(BC$4,0)),Assumptions!$F$4:$F$44))/NETWORKDAYS($K13,$L13,Assumptions!$F$4:$F$44)) -> 0
A14: 10 | B14: 1.2.2 | C14: 3 | D14: Subtask | E14: Quality audits and phase-gate reviews (4 gates) | F14: All | H14: PM | I14: 100 | J14: 300 | K14: =WORKDAY(Assumptions!$C$4,I14,Assumptions!$F$4:$F$44) -> 46468 | L14: =IF(J14=0,K14,WORKDAY(K14,J14-1,Assumptions!$F$4:$F$44)) -> 46885 | N14: 12 | O14: 0 | P14: 8 | Q14: 0 | R14: 0 | S14: 0 | T14: 0 | U14: 0 | V14: 8 | W14: 0 | X14: 0 | Y14: =SUM(N14:X14) -> 28 | Z14: =Y14*(1+Assumptions!$C$5) -> 32.2 | AA14: Gate review reports | AB14: Not started | AD14: 0 | AF14: =IF($J14=0,0,MAX(0,NETWORKDAYS(MAX($K14,AF$4),MIN($L14,EOMONTH(AF$4,0)),Assumptions!$F$4:$F$44))/NETWORKDAYS($K14,$L14,Assumptions!$F$4:$F$44)) -> 0 | AG14: =IF($J14=0,0,MAX(0,NETWORKDAYS(MAX($K14,AG$4),MIN($L14,EOMONTH(AG$4,0)),Assumptions!$F$4:$F$44))/NETWORKDAYS($K14,$L14,Assumptions!$F$4:$F$44)) -> 0 | AH14: =IF($J14=0,0,MAX(0,NETWORKDAYS(MAX($K14,AH$4),MIN($L14,EOMONTH(AH$4,0)),Assumptions!$F$4:$F$44))/NETWORKDAYS($K14,$L14,Assumptions!$F$4:$F$44)) -> 0 | AI14: =IF($J14=0,0,MAX(0,NETWORKDAYS(MAX($K14,AI$4),MIN($L14,EOMONTH(AI$4,0)),Assumptions!$F$4:$F$44))/NETWORKDAYS($K14,$L14,Assumptions!$F$4:$F$44)) -> 0 | AJ14: =IF($J14=0,0,MAX(0,NETWORKDAYS(MAX($K14,AJ$4),MIN($L14,EOMONTH(AJ$4,0)),Assumptions!$F$4:$F$44))/NETWORKDAYS($K14,$L14,Assumptions!$F$4:$F$44)) -> 0.026666667 | AK14: =IF($J14=0,0,MAX(0,NETWORKDAYS(MAX($K14,AK$4),MIN($L14,EOMONTH(AK$4,0)),Assumptions!$F$4:$F$44))/NETWORKDAYS($K14,$L14,Assumptions!$F$4:$F$44)) -> 0.073333333 | AL14: =IF($J14=0,0,MAX(0,NETWORKDAYS(MAX($K14,AL$4),MIN($L14,EOMONTH(AL$4,0)),Assumptions!$F$4:$F$44))/NETWORKDAYS($K14,$L14,Assumptions!$F$4:$F$44)) -> 0.07 | AM14: =IF($J14=0,0,MAX(0,NETWORKDAYS(MAX($K14,AM$4),MIN($L14,EOMONTH(AM$4,0)),Assumptions!$F$4:$F$44))/NETWORKDAYS($K14,$L14,Assumptions!$F$4:$F$44)) -> 0.073333333 | ... BC14: =IF($J14=0,0,MAX(0,NETWORKDAYS(MAX($K14,BC$4),MIN($L14,EOMONTH(BC$4,0)),Assumptions!$F$4:$F$44))/NETWORKDAYS($K14,$L14,Assumptions!$F$4:$F$44)) -> 0
A15: 11 | B15: 2 | C15: 1 | D15: Phase | E15: Phase 0: Inception and mobilisation | F15: Phase 0 | J15: =NETWORKDAYS(K15,L15,Assumptions!$F$4:$F$44) -> 26 | K15: =MIN(K16:K27) -> 46328 | L15: =MAX(L16:L27) -> 46363 | N15: =SUMPRODUCT(($C$16:$C$27=3)*(N16:N27)) -> 18 | O15: =SUMPRODUCT(($C$16:$C$27=3)*(O16:O27)) -> 50 | P15: =SUMPRODUCT(($C$16:$C$27=3)*(P16:P27)) -> 30 | Q15: =SUMPRODUCT(($C$16:$C$27=3)*(Q16:Q27)) -> 3 | R15: =SUMPRODUCT(($C$16:$C$27=3)*(R16:R27)) -> 15 | S15: =SUMPRODUCT(($C$16:$C$27=3)*(S16:S27)) -> 0 | T15: =SUMPRODUCT(($C$16:$C$27=3)*(T16:T27)) -> 0 | U15: =SUMPRODUCT(($C$16:$C$27=3)*(U16:U27)) -> 34 | ... X15: =SUMPRODUCT(($C$16:$C$27=3)*(X16:X27)) -> 0 | Y15: =SUM(N15:X15) -> 160 | Z15: =Y15*(1+Assumptions!$C$5) -> 184 | AF15: 0 | AG15: 0 | AH15: 0 | AI15: 0 | AJ15: 0 | AK15: 0 | AL15: 0 | AM15: 0 | AN15: 0 | AO15: 0 | AP15: 0 | AQ15: 0 | AR15: 0 | AS15: 0 | AT15: 0 | AU15: 0 | AV15: 0 | AW15: 0 | AX15: 0 | AY15: 0 | AZ15: 0 | BA15: 0 | BB15: 0 | BC15: 0
A16: 12 | B16: 2.1 | C16: 2 | D16: Task | E16: Mobilisation | F16: Phase 0 | J16: =NETWORKDAYS(K16,L16,Assumptions!$F$4:$F$44) -> 25 | K16: =MIN(K17:K20) -> 46328 | L16: =MAX(L17:L20) -> 46360 | N16: =SUMPRODUCT(($C$17:$C$20=3)*(N17:N20)) -> 11 | O16: =SUMPRODUCT(($C$17:$C$20=3)*(O17:O20)) -> 5 | P16: =SUMPRODUCT(($C$17:$C$20=3)*(P17:P20)) -> 11 | Q16: =SUMPRODUCT(($C$17:$C$20=3)*(Q17:Q20)) -> 0 | R16: =SUMPRODUCT(($C$17:$C$20=3)*(R17:R20)) -> 0 | S16: =SUMPRODUCT(($C$17:$C$20=3)*(S17:S20)) -> 0 | T16: =SUMPRODUCT(($C$17:$C$20=3)*(T17:T20)) -> 0 | U16: =SUMPRODUCT(($C$17:$C$20=3)*(U17:U20)) -> 31 | ... X16: =SUMPRODUCT(($C$17:$C$20=3)*(X17:X20)) -> 0 | Y16: =SUM(N16:X16) -> 58 | Z16: =Y16*(1+Assumptions!$C$5) -> 66.7 | AF16: 0 | AG16: 0 | AH16: 0 | AI16: 0 | AJ16: 0 | AK16: 0 | AL16: 0 | AM16: 0 | AN16: 0 | AO16: 0 | AP16: 0 | AQ16: 0 | AR16: 0 | AS16: 0 | AT16: 0 | AU16: 0 | AV16: 0 | AW16: 0 | AX16: 0 | AY16: 0 | AZ16: 0 | BA16: 0 | BB16: 0 | BC16: 0
A17: 13 | B17: 2.1.1 | C17: 3 | D17: Subtask | E17: Kick-off with GWMC and team onboarding | F17: Phase 0 | H17: PM | I17: 0 | J17: 5 | K17: =WORKDAY(Assumptions!$C$4,I17,Assumptions!$F$4:$F$44) -> 46328 | L17: =IF(J17=0,K17,WORKDAY(K17,J17-1,Assumptions!$F$4:$F$44)) -> 46332 | N17: 5 | O17: 5 | P17: 3 | Q17: 0 | R17: 0 | S17: 0 | T17: 0 | U17: 0 | V17: 0 | W17: 0 | X17: 0 | Y17: =SUM(N17:X17) -> 13 | Z17: =Y17*(1+Assumptions!$C$5) -> 14.95 | AA17: Kick-off deck, project charter | AB17: Not started | AD17: 0 | AF17: =IF($J17=0,0,MAX(0,NETWORKDAYS(MAX($K17,AF$4),MIN($L17,EOMONTH(AF$4,0)),Assumptions!$F$4:$F$44))/NETWORKDAYS($K17,$L17,Assumptions!$F$4:$F$44)) -> 1 | AG17: =IF($J17=0,0,MAX(0,NETWORKDAYS(MAX($K17,AG$4),MIN($L17,EOMONTH(AG$4,0)),Assumptions!$F$4:$F$44))/NETWORKDAYS($K17,$L17,Assumptions!$F$4:$F$44)) -> 0 | AH17: =IF($J17=0,0,MAX(0,NETWORKDAYS(MAX($K17,AH$4),MIN($L17,EOMONTH(AH$4,0)),Assumptions!$F$4:$F$44))/NETWORKDAYS($K17,$L17,Assumptions!$F$4:$F$44)) -> 0 | AI17: =IF($J17=0,0,MAX(0,NETWORKDAYS(MAX($K17,AI$4),MIN($L17,EOMONTH(AI$4,0)),Assumptions!$F$4:$F$44))/NETWORKDAYS($K17,$L17,Assumptions!$F$4:$F$44)) -> 0 | AJ17: =IF($J17=0,0,MAX(0,NETWORKDAYS(MAX($K17,AJ$4),MIN($L17,EOMONTH(AJ$4,0)),Assumptions!$F$4:$F$44))/NETWORKDAYS($K17,$L17,Assumptions!$F$4:$F$44)) -> 0 | AK17: =IF($J17=0,0,MAX(0,NETWORKDAYS(MAX($K17,AK$4),MIN($L17,EOMONTH(AK$4,0)),Assumptions!$F$4:$F$44))/NETWORKDAYS($K17,$L17,Assumptions!$F$4:$F$44)) -> 0 | AL17: =IF($J17=0,0,MAX(0,NETWORKDAYS(MAX($K17,AL$4),MIN($L17,EOMONTH(AL$4,0)),Assumptions!$F$4:$F$44))/NETWORKDAYS($K17,$L17,Assumptions!$F$4:$F$44)) -> 0 | AM17: =IF($J17=0,0,MAX(0,NETWORKDAYS(MAX($K17,AM$4),MIN($L17,EOMONTH(AM$4,0)),Assumptions!$F$4:$F$44))/NETWORKDAYS($K17,$L17,Assumptions!$F$4:$F$44)) -> 0 | ... BC17: =IF($J17=0,0,MAX(0,NETWORKDAYS(MAX($K17,BC$4),MIN($L17,EOMONTH(BC$4,0)),Assumptions!$F$4:$F$44))/NETWORKDAYS($K17,$L17,Assumptions!$F$4:$F$44)) -> 0
A18: 14 | B18: 2.1.2 | C18: 3 | D18: Subtask | E18: Tooling: repositories, CI/CD, tracker, Teams workspace | F18: Phase 0 | H18: DEV | I18: 0 | J18: 10 | K18: =WORKDAY(Assumptions!$C$4,I18,Assumptions!$F$4:$F$44) -> 46328 | L18: =IF(J18=0,K18,WORKDAY(K18,J18-1,Assumptions!$F$4:$F$44)) -> 46339 | N18: 2 | O18: 0 | P18: 3 | Q18: 0 | R18: 0 | S18: 0 | T18: 0 | U18: 10 | V18: 0 | W18: 0 | X18: 0 | Y18: =SUM(N18:X18) -> 15 | Z18: =Y18*(1+Assumptions!$C$5) -> 17.25 | AA18: Working toolchain | AB18: Not started | AD18: 0 | AF18: =IF($J18=0,0,MAX(0,NETWORKDAYS(MAX($K18,AF$4),MIN($L18,EOMONTH(AF$4,0)),Assumptions!$F$4:$F$44))/NETWORKDAYS($K18,$L18,Assumptions!$F$4:$F$44)) -> 1 | AG18: =IF($J18=0,0,MAX(0,NETWORKDAYS(MAX($K18,AG$4),MIN($L18,EOMONTH(AG$4,0)),Assumptions!$F$4:$F$44))/NETWORKDAYS($K18,$L18,Assumptions!$F$4:$F$44)) -> 0 | AH18: =IF($J18=0,0,MAX(0,NETWORKDAYS(MAX($K18,AH$4),MIN($L18,EOMONTH(AH$4,0)),Assumptions!$F$4:$F$44))/NETWORKDAYS($K18,$L18,Assumptions!$F$4:$F$44)) -> 0 | AI18: =IF($J18=0,0,MAX(0,NETWORKDAYS(MAX($K18,AI$4),MIN($L18,EOMONTH(AI$4,0)),Assumptions!$F$4:$F$44))/NETWORKDAYS($K18,$L18,Assumptions!$F$4:$F$44)) -> 0 | AJ18: =IF($J18=0,0,MAX(0,NETWORKDAYS(MAX($K18,AJ$4),MIN($L18,EOMONTH(AJ$4,0)),Assumptions!$F$4:$F$44))/NETWORKDAYS($K18,$L18,Assumptions!$F$4:$F$44)) -> 0 | AK18: =IF($J18=0,0,MAX(0,NETWORKDAYS(MAX($K18,AK$4),MIN($L18,EOMONTH(AK$4,0)),Assumptions!$F$4:$F$44))/NETWORKDAYS($K18,$L18,Assumptions!$F$4:$F$44)) -> 0 | AL18: =IF($J18=0,0,MAX(0,NETWORKDAYS(MAX($K18,AL$4),MIN($L18,EOMONTH(AL$4,0)),Assumptions!$F$4:$F$44))/NETWORKDAYS($K18,$L18,Assumptions!$F$4:$F$44)) -> 0 | AM18: =IF($J18=0,0,MAX(0,NETWORKDAYS(MAX($K18,AM$4),MIN($L18,EOMONTH(AM$4,0)),Assumptions!$F$4:$F$44))/NETWORKDAYS($K18,$L18,Assumptions!$F$4:$F$44)) -> 0 | ... BC18: =IF($J18=0,0,MAX(0,NETWORKDAYS(MAX($K18,BC$4),MIN($L18,EOMONTH(BC$4,0)),Assumptions!$F$4:$F$44))/NETWORKDAYS($K18,$L18,Assumptions!$F$4:$F$44)) -> 0
A19: 15 | B19: 2.1.3 | C19: 3 | D19: Subtask | E19: Dev and test environments provisioned | F19: Phase 0 | H19: DEV | I19: 3 | J19: 15 | K19: =WORKDAY(Assumptions!$C$4,I19,Assumptions!$F$4:$F$44) -> 46331 | L19: =IF(J19=0,K19,WORKDAY(K19,J19-1,Assumptions!$F$4:$F$44)) -> 46351 | N19: 0 | O19: 0 | P19: 3 | Q19: 0 | R19: 0 | S19: 0 | T19: 0 | U19: 15 | V19: 0 | W19: 0 | X19: 0 | Y19: =SUM(N19:X19) -> 18 | Z19: =Y19*(1+Assumptions!$C$5) -> 20.7 | AA19: Dev and test clusters | AB19: Not started | AD19: 0 | AF19: =IF($J19=0,0,MAX(0,NETWORKDAYS(MAX($K19,AF$4),MIN($L19,EOMONTH(AF$4,0)),Assumptions!$F$4:$F$44))/NETWORKDAYS($K19,$L19,Assumptions!$F$4:$F$44)) -> 1 | AG19: =IF($J19=0,0,MAX(0,NETWORKDAYS(MAX($K19,AG$4),MIN($L19,EOMONTH(AG$4,0)),Assumptions!$F$4:$F$44))/NETWORKDAYS($K19,$L19,Assumptions!$F$4:$F$44)) -> 0 | AH19: =IF($J19=0,0,MAX(0,NETWORKDAYS(MAX($K19,AH$4),MIN($L19,EOMONTH(AH$4,0)),Assumptions!$F$4:$F$44))/NETWORKDAYS($K19,$L19,Assumptions!$F$4:$F$44)) -> 0 | AI19: =IF($J19=0,0,MAX(0,NETWORKDAYS(MAX($K19,AI$4),MIN($L19,EOMONTH(AI$4,0)),Assumptions!$F$4:$F$44))/NETWORKDAYS($K19,$L19,Assumptions!$F$4:$F$44)) -> 0 | AJ19: =IF($J19=0,0,MAX(0,NETWORKDAYS(MAX($K19,AJ$4),MIN($L19,EOMONTH(AJ$4,0)),Assumptions!$F$4:$F$44))/NETWORKDAYS($K19,$L19,Assumptions!$F$4:$F$44)) -> 0 | AK19: =IF($J19=0,0,MAX(0,NETWORKDAYS(MAX($K19,AK$4),MIN($L19,EOMONTH(AK$4,0)),Assumptions!$F$4:$F$44))/NETWORKDAYS($K19,$L19,Assumptions!$F$4:$F$44)) -> 0 | AL19: =IF($J19=0,0,MAX(0,NETWORKDAYS(MAX($K19,AL$4),MIN($L19,EOMONTH(AL$4,0)),Assumptions!$F$4:$F$44))/NETWORKDAYS($K19,$L19,Assumptions!$F$4:$F$44)) -> 0 | AM19: =IF($J19=0,0,MAX(0,NETWORKDAYS(MAX($K19,AM$4),MIN($L19,EOMONTH(AM$4,0)),Assumptions!$F$4:$F$44))/NETWORKDAYS($K19,$L19,Assumptions!$F$4:$F$44)) -> 0 | ... BC19: =IF($J19=0,0,MAX(0,NETWORKDAYS(MAX($K19,BC$4),MIN($L19,EOMONTH(BC$4,0)),Assumptions!$F$4:$F$44))/NETWORKDAYS($K19,$L19,Assumptions!$F$4:$F$44)) -> 0
A20: 16 | B20: 2.1.4 | C20: 3 | D20: Subtask | E20: State Data Centre slot request and network approvals | F20: Phase 0 | H20: PM | I20: 0 | J20: 25 | K20: =WORKDAY(Assumptions!$C$4,I20,Assumptions!$F$4:$F$44) -> 46328 | L20: =IF(J20=0,K20,WORKDAY(K20,J20-1,Assumptions!$F$4:$F$44)) -> 46360 | N20: 4 | O20: 0 | P20: 2 | Q20: 0 | R20: 0 | S20: 0 | T20: 0 | U20: 6 | V20: 0 | W20: 0 | X20: 0 | Y20: =SUM(N20:X20) -> 12 | Z20: =Y20*(1+Assumptions!$C$5) -> 13.8 | AA20: SDC allocation letter | AB20: Not started | AD20: 0 | AF20: =IF($J20=0,0,MAX(0,NETWORKDAYS(MAX($K20,AF$4),MIN($L20,EOMONTH(AF$4,0)),Assumptions!$F$4:$F$44))/NETWORKDAYS($K20,$L20,Assumptions!$F$4:$F$44)) -> 0.84 | AG20: =IF($J20=0,0,MAX(0,NETWORKDAYS(MAX($K20,AG$4),MIN($L20,EOMONTH(AG$4,0)),Assumptions!$F$4:$F$44))/NETWORKDAYS($K20,$L20,Assumptions!$F$4:$F$44)) -> 0.16 | AH20: =IF($J20=0,0,MAX(0,NETWORKDAYS(MAX($K20,AH$4),MIN($L20,EOMONTH(AH$4,0)),Assumptions!$F$4:$F$44))/NETWORKDAYS($K20,$L20,Assumptions!$F$4:$F$44)) -> 0 | AI20: =IF($J20=0,0,MAX(0,NETWORKDAYS(MAX($K20,AI$4),MIN($L20,EOMONTH(AI$4,0)),Assumptions!$F$4:$F$44))/NETWORKDAYS($K20,$L20,Assumptions!$F$4:$F$44)) -> 0 | AJ20: =IF($J20=0,0,MAX(0,NETWORKDAYS(MAX($K20,AJ$4),MIN($L20,EOMONTH(AJ$4,0)),Assumptions!$F$4:$F$44))/NETWORKDAYS($K20,$L20,Assumptions!$F$4:$F$44)) -> 0 | AK20: =IF($J20=0,0,MAX(0,NETWORKDAYS(MAX($K20,AK$4),MIN($L20,EOMONTH(AK$4,0)),Assumptions!$F$4:$F$44))/NETWORKDAYS($K20,$L20,Assumptions!$F$4:$F$44)) -> 0 | AL20: =IF($J20=0,0,MAX(0,NETWORKDAYS(MAX($K20,AL$4),MIN($L20,EOMONTH(AL$4,0)),Assumptions!$F$4:$F$44))/NETWORKDAYS($K20,$L20,Assumptions!$F$4:$F$44)) -> 0 | AM20: =IF($J20=0,0,MAX(0,NETWORKDAYS(MAX($K20,AM$4),MIN($L20,EOMONTH(AM$4,0)),Assumptions!$F$4:$F$44))/NETWORKDAYS($K20,$L20,Assumptions!$F$4:$F$44)) -> 0 | ... BC20: =IF($J20=0,0,MAX(0,NETWORKDAYS(MAX($K20,BC$4),MIN($L20,EOMONTH(BC$4,0)),Assumptions!$F$4:$F$44))/NETWORKDAYS($K20,$L20,Assumptions!$F$4:$F$44)) -> 0
A21: 17 | B21: 2.2 | C21: 2 | D21: Task | E21: Requirements and design baseline | F21: Phase 0 | J21: =NETWORKDAYS(K21,L21,Assumptions!$F$4:$F$44) -> 20 | K21: =MIN(K22:K26) -> 46335 | L21: =MAX(L22:L26) -> 46360 | N21: =SUMPRODUCT(($C$22:$C$26=3)*(N22:N26)) -> 7 | O21: =SUMPRODUCT(($C$22:$C$26=3)*(O22:O26)) -> 45 | P21: =SUMPRODUCT(($C$22:$C$26=3)*(P22:P26)) -> 19 | Q21: =SUMPRODUCT(($C$22:$C$26=3)*(Q22:Q26)) -> 3 | R21: =SUMPRODUCT(($C$22:$C$26=3)*(R22:R26)) -> 15 | S21: =SUMPRODUCT(($C$22:$C$26=3)*(S22:S26)) -> 0 | T21: =SUMPRODUCT(($C$22:$C$26=3)*(T22:T26)) -> 0 | U21: =SUMPRODUCT(($C$22:$C$26=3)*(U22:U26)) -> 3 | ... X21: =SUMPRODUCT(($C$22:$C$26=3)*(X22:X26)) -> 0 | Y21: =SUM(N21:X21) -> 102 | Z21: =Y21*(1+Assumptions!$C$5) -> 117.3 | AF21: 0 | AG21: 0 | AH21: 0 | AI21: 0 | AJ21: 0 | AK21: 0 | AL21: 0 | AM21: 0 | AN21: 0 | AO21: 0 | AP21: 0 | AQ21: 0 | AR21: 0 | AS21: 0 | AT21: 0 | AU21: 0 | AV21: 0 | AW21: 0 | AX21: 0 | AY21: 0 | AZ21: 0 | BA21: 0 | BB21: 0 | BC21: 0
A22: 18 | B22: 2.2.1 | C22: 3 | D22: Subtask | E22: SRS walkthroughs with GWMC departments (Phase 1 modules) | F22: Phase 0 | H22: BA | I22: 5 | J22: 15 | K22: =WORKDAY(Assumptions!$C$4,I22,Assumptions!$F$4:$F$44) -> 46335 | L22: =IF(J22=0,K22,WORKDAY(K22,J22-1,Assumptions!$F$4:$F$44)) -> 46353 | M22: 13 | N22: 4 | O22: 25 | P22: 5 | Q22: 0 | R22: 0 | S22: 0 | T22: 0 | U22: 0 | V22: 0 | W22: 0 | X22: 0 | Y22: =SUM(N22:X22) -> 34 | Z22: =Y22*(1+Assumptions!$C$5) -> 39.1 | AA22: Workshop minutes, clarifications | AB22: Not started | AD22: 0 | AF22: =IF($J22=0,0,MAX(0,NETWORKDAYS(MAX($K22,AF$4),MIN($L22,EOMONTH(AF$4,0)),Assumptions!$F$4:$F$44))/NETWORKDAYS($K22,$L22,Assumptions!$F$4:$F$44)) -> 1 | AG22: =IF($J22=0,0,MAX(0,NETWORKDAYS(MAX($K22,AG$4),MIN($L22,EOMONTH(AG$4,0)),Assumptions!$F$4:$F$44))/NETWORKDAYS($K22,$L22,Assumptions!$F$4:$F$44)) -> 0 | AH22: =IF($J22=0,0,MAX(0,NETWORKDAYS(MAX($K22,AH$4),MIN($L22,EOMONTH(AH$4,0)),Assumptions!$F$4:$F$44))/NETWORKDAYS($K22,$L22,Assumptions!$F$4:$F$44)) -> 0 | AI22: =IF($J22=0,0,MAX(0,NETWORKDAYS(MAX($K22,AI$4),MIN($L22,EOMONTH(AI$4,0)),Assumptions!$F$4:$F$44))/NETWORKDAYS($K22,$L22,Assumptions!$F$4:$F$44)) -> 0 | AJ22: =IF($J22=0,0,MAX(0,NETWORKDAYS(MAX($K22,AJ$4),MIN($L22,EOMONTH(AJ$4,0)),Assumptions!$F$4:$F$44))/NETWORKDAYS($K22,$L22,Assumptions!$F$4:$F$44)) -> 0 | AK22: =IF($J22=0,0,MAX(0,NETWORKDAYS(MAX($K22,AK$4),MIN($L22,EOMONTH(AK$4,0)),Assumptions!$F$4:$F$44))/NETWORKDAYS($K22,$L22,Assumptions!$F$4:$F$44)) -> 0 | AL22: =IF($J22=0,0,MAX(0,NETWORKDAYS(MAX($K22,AL$4),MIN($L22,EOMONTH(AL$4,0)),Assumptions!$F$4:$F$44))/NETWORKDAYS($K22,$L22,Assumptions!$F$4:$F$44)) -> 0 | AM22: =IF($J22=0,0,MAX(0,NETWORKDAYS(MAX($K22,AM$4),MIN($L22,EOMONTH(AM$4,0)),Assumptions!$F$4:$F$44))/NETWORKDAYS($K22,$L22,Assumptions!$F$4:$F$44)) -> 0 | ... BC22: =IF($J22=0,0,MAX(0,NETWORKDAYS(MAX($K22,BC$4),MIN($L22,EOMONTH(BC$4,0)),Assumptions!$F$4:$F$44))/NETWORKDAYS($K22,$L22,Assumptions!$F$4:$F$44)) -> 0
A23: 19 | B23: 2.2.2 | C23: 3 | D23: Subtask | E23: GWMC Deployment SRS open items closed for Phase 1 | F23: Phase 0 | H23: BA | I23: 10 | J23: 15 | K23: =WORKDAY(Assumptions!$C$4,I23,Assumptions!$F$4:$F$44) -> 46342 | L23: =IF(J23=0,K23,WORKDAY(K23,J23-1,Assumptions!$F$4:$F$44)) -> 46360 | N23: 3 | O23: 12 | P23: 0 | Q23: 0 | R23: 0 | S23: 0 | T23: 0 | U23: 0 | V23: 0 | W23: 0 | X23: 0 | Y23: =SUM(N23:X23) -> 15 | Z23: =Y23*(1+Assumptions!$C$5) -> 17.25 | AA23: Signed open-items list | AB23: Not started | AD23: 0 | AF23: =IF($J23=0,0,MAX(0,NETWORKDAYS(MAX($K23,AF$4),MIN($L23,EOMONTH(AF$4,0)),Assumptions!$F$4:$F$44))/NETWORKDAYS($K23,$L23,Assumptions!$F$4:$F$44)) -> 0.73333333 | AG23: =IF($J23=0,0,MAX(0,NETWORKDAYS(MAX($K23,AG$4),MIN($L23,EOMONTH(AG$4,0)),Assumptions!$F$4:$F$44))/NETWORKDAYS($K23,$L23,Assumptions!$F$4:$F$44)) -> 0.26666667 | AH23: =IF($J23=0,0,MAX(0,NETWORKDAYS(MAX($K23,AH$4),MIN($L23,EOMONTH(AH$4,0)),Assumptions!$F$4:$F$44))/NETWORKDAYS($K23,$L23,Assumptions!$F$4:$F$44)) -> 0 | AI23: =IF($J23=0,0,MAX(0,NETWORKDAYS(MAX($K23,AI$4),MIN($L23,EOMONTH(AI$4,0)),Assumptions!$F$4:$F$44))/NETWORKDAYS($K23,$L23,Assumptions!$F$4:$F$44)) -> 0 | AJ23: =IF($J23=0,0,MAX(0,NETWORKDAYS(MAX($K23,AJ$4),MIN($L23,EOMONTH(AJ$4,0)),Assumptions!$F$4:$F$44))/NETWORKDAYS($K23,$L23,Assumptions!$F$4:$F$44)) -> 0 | AK23: =IF($J23=0,0,MAX(0,NETWORKDAYS(MAX($K23,AK$4),MIN($L23,EOMONTH(AK$4,0)),Assumptions!$F$4:$F$44))/NETWORKDAYS($K23,$L23,Assumptions!$F$4:$F$44)) -> 0 | AL23: =IF($J23=0,0,MAX(0,NETWORKDAYS(MAX($K23,AL$4),MIN($L23,EOMONTH(AL$4,0)),Assumptions!$F$4:$F$44))/NETWORKDAYS($K23,$L23,Assumptions!$F$4:$F$44)) -> 0 | AM23: =IF($J23=0,0,MAX(0,NETWORKDAYS(MAX($K23,AM$4),MIN($L23,EOMONTH(AM$4,0)),Assumptions!$F$4:$F$44))/NETWORKDAYS($K23,$L23,Assumptions!$F$4:$F$44)) -> 0 | ... BC23: =IF($J23=0,0,MAX(0,NETWORKDAYS(MAX($K23,BC$4),MIN($L23,EOMONTH(BC$4,0)),Assumptions!$F$4:$F$44))/NETWORKDAYS($K23,$L23,Assumptions!$F$4:$F$44)) -> 0
A24: 20 | B24: 2.2.3 | C24: 3 | D24: Subtask | E24: Architecture decisions (ADR-001 to 016) reviewed and signed off | F24: Phase 0 | H24: ARC | I24: 5 | J24: 15 | K24: =WORKDAY(Assumptions!$C$4,I24,Assumptions!$F$4:$F$44) -> 46335 | L24: =IF(J24=0,K24,WORKDAY(K24,J24-1,Assumptions!$F$4:$F$44)) -> 46353 | N24: 0 | O24: 0 | P24: 12 | Q24: 3 | R24: 0 | S24: 0 | T24: 0 | U24: 3 | V24: 0 | W24: 0 | X24: 0 | Y24: =SUM(N24:X24) -> 18 | Z24: =Y24*(1+Assumptions!$C$5) -> 20.7 | AA24: Signed ADRs | AB24: Not started | AD24: 0 | AF24: =IF($J24=0,0,MAX(0,NETWORKDAYS(MAX($K24,AF$4),MIN($L24,EOMONTH(AF$4,0)),Assumptions!$F$4:$F$44))/NETWORKDAYS($K24,$L24,Assumptions!$F$4:$F$44)) -> 1 | AG24: =IF($J24=0,0,MAX(0,NETWORKDAYS(MAX($K24,AG$4),MIN($L24,EOMONTH(AG$4,0)),Assumptions!$F$4:$F$44))/NETWORKDAYS($K24,$L24,Assumptions!$F$4:$F$44)) -> 0 | AH24: =IF($J24=0,0,MAX(0,NETWORKDAYS(MAX($K24,AH$4),MIN($L24,EOMONTH(AH$4,0)),Assumptions!$F$4:$F$44))/NETWORKDAYS($K24,$L24,Assumptions!$F$4:$F$44)) -> 0 | AI24: =IF($J24=0,0,MAX(0,NETWORKDAYS(MAX($K24,AI$4),MIN($L24,EOMONTH(AI$4,0)),Assumptions!$F$4:$F$44))/NETWORKDAYS($K24,$L24,Assumptions!$F$4:$F$44)) -> 0 | AJ24: =IF($J24=0,0,MAX(0,NETWORKDAYS(MAX($K24,AJ$4),MIN($L24,EOMONTH(AJ$4,0)),Assumptions!$F$4:$F$44))/NETWORKDAYS($K24,$L24,Assumptions!$F$4:$F$44)) -> 0 | AK24: =IF($J24=0,0,MAX(0,NETWORKDAYS(MAX($K24,AK$4),MIN($L24,EOMONTH(AK$4,0)),Assumptions!$F$4:$F$44))/NETWORKDAYS($K24,$L24,Assumptions!$F$4:$F$44)) -> 0 | AL24: =IF($J24=0,0,MAX(0,NETWORKDAYS(MAX($K24,AL$4),MIN($L24,EOMONTH(AL$4,0)),Assumptions!$F$4:$F$44))/NETWORKDAYS($K24,$L24,Assumptions!$F$4:$F$44)) -> 0 | AM24: =IF($J24=0,0,MAX(0,NETWORKDAYS(MAX($K24,AM$4),MIN($L24,EOMONTH(AM$4,0)),Assumptions!$F$4:$F$44))/NETWORKDAYS($K24,$L24,Assumptions!$F$4:$F$44)) -> 0 | ... BC24: =IF($J24=0,0,MAX(0,NETWORKDAYS(MAX($K24,BC$4),MIN($L24,EOMONTH(BC$4,0)),Assumptions!$F$4:$F$44))/NETWORKDAYS($K24,$L24,Assumptions!$F$4:$F$44)) -> 0
A25: 21 | B25: 2.2.4 | C25: 3 | D25: Subtask | E25: UX research, design system and accessibility baseline | F25: Phase 0 | H25: FE | I25: 5 | J25: 20 | K25: =WORKDAY(Assumptions!$C$4,I25,Assumptions!$F$4:$F$44) -> 46335 | L25: =IF(J25=0,K25,WORKDAY(K25,J25-1,Assumptions!$F$4:$F$44)) -> 46360 | N25: 0 | O25: 4 | P25: 0 | Q25: 0 | R25: 15 | S25: 0 | T25: 0 | U25: 0 | V25: 0 | W25: 0 | X25: 0 | Y25: =SUM(N25:X25) -> 19 | Z25: =Y25*(1+Assumptions!$C$5) -> 21.85 | AA25: Design system, UI kit, GIGW checklist | AB25: Not started | AD25: 0 | AF25: =IF($J25=0,0,MAX(0,NETWORKDAYS(MAX($K25,AF$4),MIN($L25,EOMONTH(AF$4,0)),Assumptions!$F$4:$F$44))/NETWORKDAYS($K25,$L25,Assumptions!$F$4:$F$44)) -> 0.8 | AG25: =IF($J25=0,0,MAX(0,NETWORKDAYS(MAX($K25,AG$4),MIN($L25,EOMONTH(AG$4,0)),Assumptions!$F$4:$F$44))/NETWORKDAYS($K25,$L25,Assumptions!$F$4:$F$44)) -> 0.2 | AH25: =IF($J25=0,0,MAX(0,NETWORKDAYS(MAX($K25,AH$4),MIN($L25,EOMONTH(AH$4,0)),Assumptions!$F$4:$F$44))/NETWORKDAYS($K25,$L25,Assumptions!$F$4:$F$44)) -> 0 | AI25: =IF($J25=0,0,MAX(0,NETWORKDAYS(MAX($K25,AI$4),MIN($L25,EOMONTH(AI$4,0)),Assumptions!$F$4:$F$44))/NETWORKDAYS($K25,$L25,Assumptions!$F$4:$F$44)) -> 0 | AJ25: =IF($J25=0,0,MAX(0,NETWORKDAYS(MAX($K25,AJ$4),MIN($L25,EOMONTH(AJ$4,0)),Assumptions!$F$4:$F$44))/NETWORKDAYS($K25,$L25,Assumptions!$F$4:$F$44)) -> 0 | AK25: =IF($J25=0,0,MAX(0,NETWORKDAYS(MAX($K25,AK$4),MIN($L25,EOMONTH(AK$4,0)),Assumptions!$F$4:$F$44))/NETWORKDAYS($K25,$L25,Assumptions!$F$4:$F$44)) -> 0 | AL25: =IF($J25=0,0,MAX(0,NETWORKDAYS(MAX($K25,AL$4),MIN($L25,EOMONTH(AL$4,0)),Assumptions!$F$4:$F$44))/NETWORKDAYS($K25,$L25,Assumptions!$F$4:$F$44)) -> 0 | AM25: =IF($J25=0,0,MAX(0,NETWORKDAYS(MAX($K25,AM$4),MIN($L25,EOMONTH(AM$4,0)),Assumptions!$F$4:$F$44))/NETWORKDAYS($K25,$L25,Assumptions!$F$4:$F$44)) -> 0 | ... BC25: =IF($J25=0,0,MAX(0,NETWORKDAYS(MAX($K25,BC$4),MIN($L25,EOMONTH(BC$4,0)),Assumptions!$F$4:$F$44))/NETWORKDAYS($K25,$L25,Assumptions!$F$4:$F$44)) -> 0
A26: 22 | B26: 2.2.5 | C26: 3 | D26: Subtask | E26: Data migration strategy and legacy data assessment | F26: Phase 0 | H26: DATA | I26: 10 | J26: 15 | K26: =WORKDAY(Assumptions!$C$4,I26,Assumptions!$F$4:$F$44) -> 46342 | L26: =IF(J26=0,K26,WORKDAY(K26,J26-1,Assumptions!$F$4:$F$44)) -> 46360 | N26: 0 | O26: 4 | P26: 2 | Q26: 0 | R26: 0 | S26: 0 | T26: 0 | U26: 0 | V26: 0 | W26: 10 | X26: 0 | Y26: =SUM(N26:X26) -> 16 | Z26: =Y26*(1+Assumptions!$C$5) -> 18.4 | AA26: Migration strategy | AB26: Not started | AD26: 0 | AF26: =IF($J26=0,0,MAX(0,NETWORKDAYS(MAX($K26,AF$4),MIN($L26,EOMONTH(AF$4,0)),Assumptions!$F$4:$F$44))/NETWORKDAYS($K26,$L26,Assumptions!$F$4:$F$44)) -> 0.73333333 | AG26: =IF($J26=0,0,MAX(0,NETWORKDAYS(MAX($K26,AG$4),MIN($L26,EOMONTH(AG$4,0)),Assumptions!$F$4:$F$44))/NETWORKDAYS($K26,$L26,Assumptions!$F$4:$F$44)) -> 0.26666667 | AH26: =IF($J26=0,0,MAX(0,NETWORKDAYS(MAX($K26,AH$4),MIN($L26,EOMONTH(AH$4,0)),Assumptions!$F$4:$F$44))/NETWORKDAYS($K26,$L26,Assumptions!$F$4:$F$44)) -> 0 | AI26: =IF($J26=0,0,MAX(0,NETWORKDAYS(MAX($K26,AI$4),MIN($L26,EOMONTH(AI$4,0)),Assumptions!$F$4:$F$44))/NETWORKDAYS($K26,$L26,Assumptions!$F$4:$F$44)) -> 0 | AJ26: =IF($J26=0,0,MAX(0,NETWORKDAYS(MAX($K26,AJ$4),MIN($L26,EOMONTH(AJ$4,0)),Assumptions!$F$4:$F$44))/NETWORKDAYS($K26,$L26,Assumptions!$F$4:$F$44)) -> 0 | AK26: =IF($J26=0,0,MAX(0,NETWORKDAYS(MAX($K26,AK$4),MIN($L26,EOMONTH(AK$4,0)),Assumptions!$F$4:$F$44))/NETWORKDAYS($K26,$L26,Assumptions!$F$4:$F$44)) -> 0 | AL26: =IF($J26=0,0,MAX(0,NETWORKDAYS(MAX($K26,AL$4),MIN($L26,EOMONTH(AL$4,0)),Assumptions!$F$4:$F$44))/NETWORKDAYS($K26,$L26,Assumptions!$F$4:$F$44)) -> 0 | AM26: =IF($J26=0,0,MAX(0,NETWORKDAYS(MAX($K26,AM$4),MIN($L26,EOMONTH(AM$4,0)),Assumptions!$F$4:$F$44))/NETWORKDAYS($K26,$L26,Assumptions!$F$4:$F$44)) -> 0 | ... BC26: =IF($J26=0,0,MAX(0,NETWORKDAYS(MAX($K26,BC$4),MIN($L26,EOMONTH(BC$4,0)),Assumptions!$F$4:$F$44))/NETWORKDAYS($K26,$L26,Assumptions!$F$4:$F$44)) -> 0
A27: 23 | B27: 2.3 | C27: 2 | D27: Milestone | E27: M0: Inception complete, Phase 1 build starts | F27: Phase 0 | I27: 25 | J27: 0 | K27: =WORKDAY(Assumptions!$C$4,I27,Assumptions!$F$4:$F$44) -> 46363 | L27: =IF(J27=0,K27,WORKDAY(K27,J27-1,Assumptions!$F$4:$F$44)) -> 46363 | M27: 18,20 | N27: 0 | O27: 0 | P27: 0 | Q27: 0 | R27: 0 | S27: 0 | T27: 0 | U27: 0 | V27: 0 | W27: 0 | X27: 0 | Y27: =SUM(N27:X27) -> 0 | Z27: =Y27*(1+Assumptions!$C$5) -> 0 | AB27: Not started | AD27: 0 | AF27: 0 | AG27: 0 | AH27: 0 | AI27: 0 | AJ27: 0 | AK27: 0 | AL27: 0 | AM27: 0 | AN27: 0 | AO27: 0 | AP27: 0 | AQ27: 0 | AR27: 0 | AS27: 0 | AT27: 0 | AU27: 0 | AV27: 0 | AW27: 0 | AX27: 0 | AY27: 0 | AZ27: 0 | BA27: 0 | BB27: 0 | BC27: 0
A28: 24 | B28: 3 | C28: 1 | D28: Phase | E28: Platform foundation (built in Phase 1) | F28: Phase 1 | J28: =NETWORKDAYS(K28,L28,Assumptions!$F$4:$F$44) -> 84 | K28: =MIN(K29:K105) -> 46342 | L28: =MAX(L29:L105) -> 46457 | N28: =SUMPRODUCT(($C$29:$C$105=3)*(N29:N105)) -> 0 | O28: =SUMPRODUCT(($C$29:$C$105=3)*(O29:O105)) -> 15 | P28: =SUMPRODUCT(($C$29:$C$105=3)*(P29:P105)) -> 56 | Q28: =SUMPRODUCT(($C$29:$C$105=3)*(Q29:Q105)) -> 320 | R28: =SUMPRODUCT(($C$29:$C$105=3)*(R29:R105)) -> 97 | S28: =SUMPRODUCT(($C$29:$C$105=3)*(S29:S105)) -> 49 | T28: =SUMPRODUCT(($C$29:$C$105=3)*(T29:T105)) -> 32 | U28: =SUMPRODUCT(($C$29:$C$105=3)*(U29:U105)) -> 95 | ... X28: =SUMPRODUCT(($C$29:$C$105=3)*(X29:X105)) -> 0 | Y28: =SUM(N28:X28) -> 785 | Z28: =Y28*(1+Assumptions!$C$5) -> 902.75 | AF28: 0 | AG28: 0 | AH28: 0 | AI28: 0 | AJ28: 0 | AK28: 0 | AL28: 0 | AM28: 0 | AN28: 0 | AO28: 0 | AP28: 0 | AQ28: 0 | AR28: 0 | AS28: 0 | AT28: 0 | AU28: 0 | AV28: 0 | AW28: 0 | AX28: 0 | AY28: 0 | AZ28: 0 | BA28: 0 | BB28: 0 | BC28: 0
A29: 25 | B29: 3.1 | C29: 2 | D29: Task | E29: Identity, OTP, CAPTCHA and step-up (Keycloak) | F29: Phase 1 | G29: Platform | J29: =NETWORKDAYS(K29,L29,Assumptions!$F$4:$F$44) -> 51 | K29: =MIN(K30:K32) -> 46342 | L29: =MAX(L30:L32) -> 46412 | N29: =SUMPRODUCT(($C$30:$C$32=3)*(N30:N32)) -> 0 | O29: =SUMPRODUCT(($C$30:$C$32=3)*(O30:O32)) -> 0 | P29: =SUMPRODUCT(($C$30:$C$32=3)*(P30:P32)) -> 4 | Q29: =SUMPRODUCT(($C$30:$C$32=3)*(Q30:Q32)) -> 33 | R29: =SUMPRODUCT(($C$30:$C$32=3)*(R30:R32)) -> 7 | S29: =SUMPRODUCT(($C$30:$C$32=3)*(S30:S32)) -> 0 | T29: =SUMPRODUCT(($C$30:$C$32=3)*(T30:T32)) -> 0 | U29: =SUMPRODUCT(($C$30:$C$32=3)*(U30:U32)) -> 4 | ... X29: =SUMPRODUCT(($C$30:$C$32=3)*(X30:X32)) -> 0 | Y29: =SUM(N29:X29) -> 58 | Z29: =Y29*(1+Assumptions!$C$5) -> 66.7 | AA29: PLT-FR-001, 026, 028 to 032 | AF29: 0 | AG29: 0 | AH29: 0 | AI29: 0 | AJ29: 0 | AK29: 0 | AL29: 0 | AM29: 0 | AN29: 0 | AO29: 0 | AP29: 0 | AQ29: 0 | AR29: 0 | AS29: 0 | AT29: 0 | AU29: 0 | AV29: 0 | AW29: 0 | AX29: 0 | AY29: 0 | AZ29: 0 | BA29: 0 | BB29: 0 | BC29: 0
A30: 26 | B30: 3.1.1 | C30: 3 | D30: Subtask | E30: Detailed design and contracts | F30: Phase 1 | G30: Platform | H30: ARC | I30: 10 | J30: 10 | K30: =WORKDAY(Assumptions!$C$4,I30,Assumptions!$F$4:$F$44) -> 46342 | L30: =IF(J30=0,K30,WORKDAY(K30,J30-1,Assumptions!$F$4:$F$44)) -> 46353 | M30: 20 | N30: 0 | O30: 0 | P30: 4 | Q30: 3 | R30: 0 | S30: 0 | T30: 0 | U30: 0 | V30: 0 | W30: 0 | X30: 0 | Y30: =SUM(N30:X30) -> 7 | Z30: =Y30*(1+Assumptions!$C$5) -> 8.05 | AA30: Design note, OpenAPI and event schemas | AB30: Not started | AD30: 0 | AF30: =IF($J30=0,0,MAX(0,NETWORKDAYS(MAX($K30,AF$4),MIN($L30,EOMONTH(AF$4,0)),Assumptions!$F$4:$F$44))/NETWORKDAYS($K30,$L30,Assumptions!$F$4:$F$44)) -> 1 | AG30: =IF($J30=0,0,MAX(0,NETWORKDAYS(MAX($K30,AG$4),MIN($L30,EOMONTH(AG$4,0)),Assumptions!$F$4:$F$44))/NETWORKDAYS($K30,$L30,Assumptions!$F$4:$F$44)) -> 0 | AH30: =IF($J30=0,0,MAX(0,NETWORKDAYS(MAX($K30,AH$4),MIN($L30,EOMONTH(AH$4,0)),Assumptions!$F$4:$F$44))/NETWORKDAYS($K30,$L30,Assumptions!$F$4:$F$44)) -> 0 | AI30: =IF($J30=0,0,MAX(0,NETWORKDAYS(MAX($K30,AI$4),MIN($L30,EOMONTH(AI$4,0)),Assumptions!$F$4:$F$44))/NETWORKDAYS($K30,$L30,Assumptions!$F$4:$F$44)) -> 0 | AJ30: =IF($J30=0,0,MAX(0,NETWORKDAYS(MAX($K30,AJ$4),MIN($L30,EOMONTH(AJ$4,0)),Assumptions!$F$4:$F$44))/NETWORKDAYS($K30,$L30,Assumptions!$F$4:$F$44)) -> 0 | AK30: =IF($J30=0,0,MAX(0,NETWORKDAYS(MAX($K30,AK$4),MIN($L30,EOMONTH(AK$4,0)),Assumptions!$F$4:$F$44))/NETWORKDAYS($K30,$L30,Assumptions!$F$4:$F$44)) -> 0 | AL30: =IF($J30=0,0,MAX(0,NETWORKDAYS(MAX($K30,AL$4),MIN($L30,EOMONTH(AL$4,0)),Assumptions!$F$4:$F$44))/NETWORKDAYS($K30,$L30,Assumptions!$F$4:$F$44)) -> 0 | AM30: =IF($J30=0,0,MAX(0,NETWORKDAYS(MAX($K30,AM$4),MIN($L30,EOMONTH(AM$4,0)),Assumptions!$F$4:$F$44))/NETWORKDAYS($K30,$L30,Assumptions!$F$4:$F$44)) -> 0 | ... BC30: =IF($J30=0,0,MAX(0,NETWORKDAYS(MAX($K30,BC$4),MIN($L30,EOMONTH(BC$4,0)),Assumptions!$F$4:$F$44))/NETWORKDAYS($K30,$L30,Assumptions!$F$4:$F$44)) -> 0
A31: 27 | B31: 3.1.2 | C31: 3 | D31: Subtask | E31: Build and unit tests | F31: Phase 1 | G31: Platform | H31: BE | I31: 20 | J31: 30 | K31: =WORKDAY(Assumptions!$C$4,I31,Assumptions!$F$4:$F$44) -> 46356 | L31: =IF(J31=0,K31,WORKDAY(K31,J31-1,Assumptions!$F$4:$F$44)) -> 46395 | N31: 0 | O31: 0 | P31: 0 | Q31: 27 | R31: 7 | S31: 0 | T31: 0 | U31: 4 | V31: 0 | W31: 0 | X31: 0 | Y31: =SUM(N31:X31) -> 38 | Z31: =Y31*(1+Assumptions!$C$5) -> 43.7 | AA31: Working service | AB31: Not started | AD31: 0 | AF31: =IF($J31=0,0,MAX(0,NETWORKDAYS(MAX($K31,AF$4),MIN($L31,EOMONTH(AF$4,0)),Assumptions!$F$4:$F$44))/NETWORKDAYS($K31,$L31,Assumptions!$F$4:$F$44)) -> 0.033333333 | AG31: =IF($J31=0,0,MAX(0,NETWORKDAYS(MAX($K31,AG$4),MIN($L31,EOMONTH(AG$4,0)),Assumptions!$F$4:$F$44))/NETWORKDAYS($K31,$L31,Assumptions!$F$4:$F$44)) -> 0.76666667 | AH31: =IF($J31=0,0,MAX(0,NETWORKDAYS(MAX($K31,AH$4),MIN($L31,EOMONTH(AH$4,0)),Assumptions!$F$4:$F$44))/NETWORKDAYS($K31,$L31,Assumptions!$F$4:$F$44)) -> 0.2 | AI31: =IF($J31=0,0,MAX(0,NETWORKDAYS(MAX($K31,AI$4),MIN($L31,EOMONTH(AI$4,0)),Assumptions!$F$4:$F$44))/NETWORKDAYS($K31,$L31,Assumptions!$F$4:$F$44)) -> 0 | AJ31: =IF($J31=0,0,MAX(0,NETWORKDAYS(MAX($K31,AJ$4),MIN($L31,EOMONTH(AJ$4,0)),Assumptions!$F$4:$F$44))/NETWORKDAYS($K31,$L31,Assumptions!$F$4:$F$44)) -> 0 | AK31: =IF($J31=0,0,MAX(0,NETWORKDAYS(MAX($K31,AK$4),MIN($L31,EOMONTH(AK$4,0)),Assumptions!$F$4:$F$44))/NETWORKDAYS($K31,$L31,Assumptions!$F$4:$F$44)) -> 0 | AL31: =IF($J31=0,0,MAX(0,NETWORKDAYS(MAX($K31,AL$4),MIN($L31,EOMONTH(AL$4,0)),Assumptions!$F$4:$F$44))/NETWORKDAYS($K31,$L31,Assumptions!$F$4:$F$44)) -> 0 | AM31: =IF($J31=0,0,MAX(0,NETWORKDAYS(MAX($K31,AM$4),MIN($L31,EOMONTH(AM$4,0)),Assumptions!$F$4:$F$44))/NETWORKDAYS($K31,$L31,Assumptions!$F$4:$F$44)) -> 0 | ... BC31: =IF($J31=0,0,MAX(0,NETWORKDAYS(MAX($K31,BC$4),MIN($L31,EOMONTH(BC$4,0)),Assumptions!$F$4:$F$44))/NETWORKDAYS($K31,$L31,Assumptions!$F$4:$F$44)) -> 0
A32: 28 | B32: 3.1.3 | C32: 3 | D32: Subtask | E32: Component, security and contract tests | F32: Phase 1 | G32: Platform | H32: QA | I32: 48 | J32: 13 | K32: =WORKDAY(Assumptions!$C$4,I32,Assumptions!$F$4:$F$44) -> 46394 | L32: =IF(J32=0,K32,WORKDAY(K32,J32-1,Assumptions!$F$4:$F$44)) -> 46412 | N32: 0 | O32: 0 | P32: 0 | Q32: 3 | R32: 0 | S32: 0 | T32: 0 | U32: 0 | V32: 10 | W32: 0 | X32: 0 | Y32: =SUM(N32:X32) -> 13 | Z32: =Y32*(1+Assumptions!$C$5) -> 14.95 | AA32: Test report | AB32: Not started | AD32: 0 | AF32: =IF($J32=0,0,MAX(0,NETWORKDAYS(MAX($K32,AF$4),MIN($L32,EOMONTH(AF$4,0)),Assumptions!$F$4:$F$44))/NETWORKDAYS($K32,$L32,Assumptions!$F$4:$F$44)) -> 0 | AG32: =IF($J32=0,0,MAX(0,NETWORKDAYS(MAX($K32,AG$4),MIN($L32,EOMONTH(AG$4,0)),Assumptions!$F$4:$F$44))/NETWORKDAYS($K32,$L32,Assumptions!$F$4:$F$44)) -> 0 | AH32: =IF($J32=0,0,MAX(0,NETWORKDAYS(MAX($K32,AH$4),MIN($L32,EOMONTH(AH$4,0)),Assumptions!$F$4:$F$44))/NETWORKDAYS($K32,$L32,Assumptions!$F$4:$F$44)) -> 1 | AI32: =IF($J32=0,0,MAX(0,NETWORKDAYS(MAX($K32,AI$4),MIN($L32,EOMONTH(AI$4,0)),Assumptions!$F$4:$F$44))/NETWORKDAYS($K32,$L32,Assumptions!$F$4:$F$44)) -> 0 | AJ32: =IF($J32=0,0,MAX(0,NETWORKDAYS(MAX($K32,AJ$4),MIN($L32,EOMONTH(AJ$4,0)),Assumptions!$F$4:$F$44))/NETWORKDAYS($K32,$L32,Assumptions!$F$4:$F$44)) -> 0 | AK32: =IF($J32=0,0,MAX(0,NETWORKDAYS(MAX($K32,AK$4),MIN($L32,EOMONTH(AK$4,0)),Assumptions!$F$4:$F$44))/NETWORKDAYS($K32,$L32,Assumptions!$F$4:$F$44)) -> 0 | AL32: =IF($J32=0,0,MAX(0,NETWORKDAYS(MAX($K32,AL$4),MIN($L32,EOMONTH(AL$4,0)),Assumptions!$F$4:$F$44))/NETWORKDAYS($K32,$L32,Assumptions!$F$4:$F$44)) -> 0 | AM32: =IF($J32=0,0,MAX(0,NETWORKDAYS(MAX($K32,AM$4),MIN($L32,EOMONTH(AM$4,0)),Assumptions!$F$4:$F$44))/NETWORKDAYS($K32,$L32,Assumptions!$F$4:$F$44)) -> 0 | ... BC32: =IF($J32=0,0,MAX(0,NETWORKDAYS(MAX($K32,BC$4),MIN($L32,EOMONTH(BC$4,0)),Assumptions!$F$4:$F$44))/NETWORKDAYS($K32,$L32,Assumptions!$F$4:$F$44)) -> 0
A33: 29 | B33: 3.2 | C33: 2 | D33: Task | E33: Tenant, configuration console and Telangana state pack | F33: Phase 1 | G33: Platform | J33: =NETWORKDAYS(K33,L33,Assumptions!$F$4:$F$44) -> 50 | K33: =MIN(K34:K36) -> 46350 | L33: =MAX(L34:L36) -> 46419 | N33: =SUMPRODUCT(($C$34:$C$36=3)*(N34:N36)) -> 0 | O33: =SUMPRODUCT(($C$34:$C$36=3)*(O34:O36)) -> 7 | P33: =SUMPRODUCT(($C$34:$C$36=3)*(P34:P36)) -> 3 | Q33: =SUMPRODUCT(($C$34:$C$36=3)*(Q34:Q36)) -> 26 | R33: =SUMPRODUCT(($C$34:$C$36=3)*(R34:R36)) -> 14 | S33: =SUMPRODUCT(($C$34:$C$36=3)*(S34:S36)) -> 0 | T33: =SUMPRODUCT(($C$34:$C$36=3)*(T34:T36)) -> 0 | U33: =SUMPRODUCT(($C$34:$C$36=3)*(U34:U36)) -> 0 | ... X33: =SUMPRODUCT(($C$34:$C$36=3)*(X34:X36)) -> 0 | Y33: =SUM(N33:X33) -> 58 | Z33: =Y33*(1+Assumptions!$C$5) -> 66.7 | AA33: PLT-FR-015 to 018, 022 | AF33: 0 | AG33: 0 | AH33: 0 | AI33: 0 | AJ33: 0 | AK33: 0 | AL33: 0 | AM33: 0 | AN33: 0 | AO33: 0 | AP33: 0 | AQ33: 0 | AR33: 0 | AS33: 0 | AT33: 0 | AU33: 0 | AV33: 0 | AW33: 0 | AX33: 0 | AY33: 0 | AZ33: 0 | BA33: 0 | BB33: 0 | BC33: 0
A34: 30 | B34: 3.2.1 | C34: 3 | D34: Subtask | E34: Detailed design and contracts | F34: Phase 1 | G34: Platform | H34: ARC | I34: 16 | J34: 10 | K34: =WORKDAY(Assumptions!$C$4,I34,Assumptions!$F$4:$F$44) -> 46350 | L34: =IF(J34=0,K34,WORKDAY(K34,J34-1,Assumptions!$F$4:$F$44)) -> 46363 | M34: 20 | N34: 0 | O34: 0 | P34: 3 | Q34: 2 | R34: 0 | S34: 0 | T34: 0 | U34: 0 | V34: 0 | W34: 0 | X34: 0 | Y34: =SUM(N34:X34) -> 5 | Z34: =Y34*(1+Assumptions!$C$5) -> 5.75 | AA34: Design note, OpenAPI and event schemas | AB34: Not started | AD34: 0 | AF34: =IF($J34=0,0,MAX(0,NETWORKDAYS(MAX($K34,AF$4),MIN($L34,EOMONTH(AF$4,0)),Assumptions!$F$4:$F$44))/NETWORKDAYS($K34,$L34,Assumptions!$F$4:$F$44)) -> 0.5 | AG34: =IF($J34=0,0,MAX(0,NETWORKDAYS(MAX($K34,AG$4),MIN($L34,EOMONTH(AG$4,0)),Assumptions!$F$4:$F$44))/NETWORKDAYS($K34,$L34,Assumptions!$F$4:$F$44)) -> 0.5 | AH34: =IF($J34=0,0,MAX(0,NETWORKDAYS(MAX($K34,AH$4),MIN($L34,EOMONTH(AH$4,0)),Assumptions!$F$4:$F$44))/NETWORKDAYS($K34,$L34,Assumptions!$F$4:$F$44)) -> 0 | AI34: =IF($J34=0,0,MAX(0,NETWORKDAYS(MAX($K34,AI$4),MIN($L34,EOMONTH(AI$4,0)),Assumptions!$F$4:$F$44))/NETWORKDAYS($K34,$L34,Assumptions!$F$4:$F$44)) -> 0 | AJ34: =IF($J34=0,0,MAX(0,NETWORKDAYS(MAX($K34,AJ$4),MIN($L34,EOMONTH(AJ$4,0)),Assumptions!$F$4:$F$44))/NETWORKDAYS($K34,$L34,Assumptions!$F$4:$F$44)) -> 0 | AK34: =IF($J34=0,0,MAX(0,NETWORKDAYS(MAX($K34,AK$4),MIN($L34,EOMONTH(AK$4,0)),Assumptions!$F$4:$F$44))/NETWORKDAYS($K34,$L34,Assumptions!$F$4:$F$44)) -> 0 | AL34: =IF($J34=0,0,MAX(0,NETWORKDAYS(MAX($K34,AL$4),MIN($L34,EOMONTH(AL$4,0)),Assumptions!$F$4:$F$44))/NETWORKDAYS($K34,$L34,Assumptions!$F$4:$F$44)) -> 0 | AM34: =IF($J34=0,0,MAX(0,NETWORKDAYS(MAX($K34,AM$4),MIN($L34,EOMONTH(AM$4,0)),Assumptions!$F$4:$F$44))/NETWORKDAYS($K34,$L34,Assumptions!$F$4:$F$44)) -> 0 | ... BC34: =IF($J34=0,0,MAX(0,NETWORKDAYS(MAX($K34,BC$4),MIN($L34,EOMONTH(BC$4,0)),Assumptions!$F$4:$F$44))/NETWORKDAYS($K34,$L34,Assumptions!$F$4:$F$44)) -> 0
A35: 31 | B35: 3.2.2 | C35: 3 | D35: Subtask | E35: Build and unit tests | F35: Phase 1 | G35: Platform | H35: BE | I35: 26 | J35: 30 | K35: =WORKDAY(Assumptions!$C$4,I35,Assumptions!$F$4:$F$44) -> 46364 | L35: =IF(J35=0,K35,WORKDAY(K35,J35-1,Assumptions!$F$4:$F$44)) -> 46405 | N35: 0 | O35: 7 | P35: 0 | Q35: 22 | R35: 14 | S35: 0 | T35: 0 | U35: 0 | V35: 0 | W35: 0 | X35: 0 | Y35: =SUM(N35:X35) -> 43 | Z35: =Y35*(1+Assumptions!$C$5) -> 49.45 | AA35: Working service | AB35: Not started | AD35: 0 | AF35: =IF($J35=0,0,MAX(0,NETWORKDAYS(MAX($K35,AF$4),MIN($L35,EOMONTH(AF$4,0)),Assumptions!$F$4:$F$44))/NETWORKDAYS($K35,$L35,Assumptions!$F$4:$F$44)) -> 0 | AG35: =IF($J35=0,0,MAX(0,NETWORKDAYS(MAX($K35,AG$4),MIN($L35,EOMONTH(AG$4,0)),Assumptions!$F$4:$F$44))/NETWORKDAYS($K35,$L35,Assumptions!$F$4:$F$44)) -> 0.6 | AH35: =IF($J35=0,0,MAX(0,NETWORKDAYS(MAX($K35,AH$4),MIN($L35,EOMONTH(AH$4,0)),Assumptions!$F$4:$F$44))/NETWORKDAYS($K35,$L35,Assumptions!$F$4:$F$44)) -> 0.4 | AI35: =IF($J35=0,0,MAX(0,NETWORKDAYS(MAX($K35,AI$4),MIN($L35,EOMONTH(AI$4,0)),Assumptions!$F$4:$F$44))/NETWORKDAYS($K35,$L35,Assumptions!$F$4:$F$44)) -> 0 | AJ35: =IF($J35=0,0,MAX(0,NETWORKDAYS(MAX($K35,AJ$4),MIN($L35,EOMONTH(AJ$4,0)),Assumptions!$F$4:$F$44))/NETWORKDAYS($K35,$L35,Assumptions!$F$4:$F$44)) -> 0 | AK35: =IF($J35=0,0,MAX(0,NETWORKDAYS(MAX($K35,AK$4),MIN($L35,EOMONTH(AK$4,0)),Assumptions!$F$4:$F$44))/NETWORKDAYS($K35,$L35,Assumptions!$F$4:$F$44)) -> 0 | AL35: =IF($J35=0,0,MAX(0,NETWORKDAYS(MAX($K35,AL$4),MIN($L35,EOMONTH(AL$4,0)),Assumptions!$F$4:$F$44))/NETWORKDAYS($K35,$L35,Assumptions!$F$4:$F$44)) -> 0 | AM35: =IF($J35=0,0,MAX(0,NETWORKDAYS(MAX($K35,AM$4),MIN($L35,EOMONTH(AM$4,0)),Assumptions!$F$4:$F$44))/NETWORKDAYS($K35,$L35,Assumptions!$F$4:$F$44)) -> 0 | ... BC35: =IF($J35=0,0,MAX(0,NETWORKDAYS(MAX($K35,BC$4),MIN($L35,EOMONTH(BC$4,0)),Assumptions!$F$4:$F$44))/NETWORKDAYS($K35,$L35,Assumptions!$F$4:$F$44)) -> 0
A36: 32 | B36: 3.2.3 | C36: 3 | D36: Subtask | E36: Component, security and contract tests | F36: Phase 1 | G36: Platform | H36: QA | I36: 53 | J36: 13 | K36: =WORKDAY(Assumptions!$C$4,I36,Assumptions!$F$4:$F$44) -> 46401 | L36: =IF(J36=0,K36,WORKDAY(K36,J36-1,Assumptions!$F$4:$F$44)) -> 46419 | N36: 0 | O36: 0 | P36: 0 | Q36: 2 | R36: 0 | S36: 0 | T36: 0 | U36: 0 | V36: 8 | W36: 0 | X36: 0 | Y36: =SUM(N36:X36) -> 10 | Z36: =Y36*(1+Assumptions!$C$5) -> 11.5 | AA36: Test report | AB36: Not started | AD36: 0 | AF36: =IF($J36=0,0,MAX(0,NETWORKDAYS(MAX($K36,AF$4),MIN($L36,EOMONTH(AF$4,0)),Assumptions!$F$4:$F$44))/NETWORKDAYS($K36,$L36,Assumptions!$F$4:$F$44)) -> 0 | AG36: =IF($J36=0,0,MAX(0,NETWORKDAYS(MAX($K36,AG$4),MIN($L36,EOMONTH(AG$4,0)),Assumptions!$F$4:$F$44))/NETWORKDAYS($K36,$L36,Assumptions!$F$4:$F$44)) -> 0 | AH36: =IF($J36=0,0,MAX(0,NETWORKDAYS(MAX($K36,AH$4),MIN($L36,EOMONTH(AH$4,0)),Assumptions!$F$4:$F$44))/NETWORKDAYS($K36,$L36,Assumptions!$F$4:$F$44)) -> 0.92307692 | AI36: =IF($J36=0,0,MAX(0,NETWORKDAYS(MAX($K36,AI$4),MIN($L36,EOMONTH(AI$4,0)),Assumptions!$F$4:$F$44))/NETWORKDAYS($K36,$L36,Assumptions!$F$4:$F$44)) -> 0.076923077 | AJ36: =IF($J36=0,0,MAX(0,NETWORKDAYS(MAX($K36,AJ$4),MIN($L36,EOMONTH(AJ$4,0)),Assumptions!$F$4:$F$44))/NETWORKDAYS($K36,$L36,Assumptions!$F$4:$F$44)) -> 0 | AK36: =IF($J36=0,0,MAX(0,NETWORKDAYS(MAX($K36,AK$4),MIN($L36,EOMONTH(AK$4,0)),Assumptions!$F$4:$F$44))/NETWORKDAYS($K36,$L36,Assumptions!$F$4:$F$44)) -> 0 | AL36: =IF($J36=0,0,MAX(0,NETWORKDAYS(MAX($K36,AL$4),MIN($L36,EOMONTH(AL$4,0)),Assumptions!$F$4:$F$44))/NETWORKDAYS($K36,$L36,Assumptions!$F$4:$F$44)) -> 0 | AM36: =IF($J36=0,0,MAX(0,NETWORKDAYS(MAX($K36,AM$4),MIN($L36,EOMONTH(AM$4,0)),Assumptions!$F$4:$F$44))/NETWORKDAYS($K36,$L36,Assumptions!$F$4:$F$44)) -> 0 | ... BC36: =IF($J36=0,0,MAX(0,NETWORKDAYS(MAX($K36,BC$4),MIN($L36,EOMONTH(BC$4,0)),Assumptions!$F$4:$F$44))/NETWORKDAYS($K36,$L36,Assumptions!$F$4:$F$44)) -> 0
A37: 33 | B37: 3.3 | C37: 2 | D37: Task | E37: Workflow and rules engine (Flowable BPMN and DMN) | F37: Phase 1 | G37: Platform | J37: =NETWORKDAYS(K37,L37,Assumptions!$F$4:$F$44) -> 50 | K37: =MIN(K38:K40) -> 46350 | L37: =MAX(L38:L40) -> 46419 | N37: =SUMPRODUCT(($C$38:$C$40=3)*(N38:N40)) -> 0 | O37: =SUMPRODUCT(($C$38:$C$40=3)*(O38:O40)) -> 0 | P37: =SUMPRODUCT(($C$38:$C$40=3)*(P38:P40)) -> 4 | Q37: =SUMPRODUCT(($C$38:$C$40=3)*(Q38:Q40)) -> 31 | R37: =SUMPRODUCT(($C$38:$C$40=3)*(R38:R40)) -> 9 | S37: =SUMPRODUCT(($C$38:$C$40=3)*(S38:S40)) -> 0 | T37: =SUMPRODUCT(($C$38:$C$40=3)*(T38:T40)) -> 0 | U37: =SUMPRODUCT(($C$38:$C$40=3)*(U38:U40)) -> 0 | ... X37: =SUMPRODUCT(($C$38:$C$40=3)*(X38:X40)) -> 0 | Y37: =SUM(N37:X37) -> 52 | Z37: =Y37*(1+Assumptions!$C$5) -> 59.8 | AA37: PLT-FR-003, 004 | AF37: 0 | AG37: 0 | AH37: 0 | AI37: 0 | AJ37: 0 | AK37: 0 | AL37: 0 | AM37: 0 | AN37: 0 | AO37: 0 | AP37: 0 | AQ37: 0 | AR37: 0 | AS37: 0 | AT37: 0 | AU37: 0 | AV37: 0 | AW37: 0 | AX37: 0 | AY37: 0 | AZ37: 0 | BA37: 0 | BB37: 0 | BC37: 0
